Workbook

Sheet README
A1: FeFET 2×2 어레이 — distance(1-D 교정 → 2-D 질의 예측) 실험 정리
A3: 작성 | B3: 2026-09-06 15:40, Claude (실험: Aiden-Byun, chipX, FPGA COM4, TIA readout)
A4: 목적 | B4: 어레이에서 열별 1-D 교정(v0, κ, S)만으로 두 열 동시 질의(2-D)의 row 전류를 예측하는 거리함수의 정확도(row R²)를 읽기 조건으로 최대화
A5: 배선 | B5: cell(r,c) = FeFET A(gate SL_Ac) + FeFET B(gate SL_Bc) 상보 쌍. col0: DAC11/12, col1: DAC13/14. row r: ML_Fr → RBL/TIA12,13 ; MBL_Fr → DAC20,30 (INH floating 가능)
A6: 읽기 방식 | B6: TIA. MBL(=READ_V) 바이어스 → row 합 전류가 ADC code 로. 게이트: SL_A = C + x, SL_B = C − x (상보 스윕). 저장값 v0 에서 전류 최소(노치).
A7: 모델 | B7: I_r(x) = S_r + Σ_c κ_rc (x_c − v0_rc)² (2차, |x−v0| ≤ fit 창). 교정: 열 c 만 스윕(다른 열 x=0) → v0, κ, m ; S_r 은 두 스윕에서 과결정(차이 = S_check).
A8: 지표 | B8: row R² = 1 − RMSE²/var(측정) (row 별 24 질의). score = 두 row 평균 (2차 예측 / 곡선-중첩 예측 중 큰 쪽; 실제로는 전부 2차). SNR = 질의 간 예측 excess σ / 2차 RMSE. noise = 질의 3샘플 표준편차 평균 [code]. headroom = TIA 클립(2880) − 스윕 최대 code. depth = 노치 깊이.
A9: 손잡이 | B9: span: 질의 x 범위 ±[V] · mbl: READ_V [V] · center_d: C(−0.93) 오프셋 · sweep_half: 교정 스윕 창 ±[V] · fit_half: 2차 fit 창 ±[V] · samples: 질의당 ADC 샘플 수
A10: 실험 흐름 | B10: 0905 13:31 영점(arrauto) → 0905 15:00 캠페인 v1 (span 0.2~0.5) → 0905 16:45 캠페인 v2 (span 0.3~0.6, 기준 재측정) → 0906 09:59~15:29 최적화 138 라운드 (fefet_array_night, 읽기 전용, 쓰기 펄스 없음)
A11: 최종 권장 | B11: READ_V −1.75 V, C −0.93 V, span ±0.7 V, 스윕 창 ±0.7 V, 2차 fit 창 ±0.6 V, samples 3 → row R² 0.985 (0.98~0.99), RMSE ≈ 5.4 code ≈ noise, SNR ≈ 8.5, κ ≈ 226 code/V², headroom ≈ 1260
A12: 한계 | B12: R² 향상은 전부 신호 분산 증가(span, |MBL|)에서 옴 — 잔차는 처음부터 readout 노이즈 수준(5~7 code). 분해능: span 0.7 에서 초과전류 ~110 code / σ 5~7 → 2σ 기준 8~10 단계, 노치 근처는 기울기 0. samples 1 은 0.948 로 부족, 6 은 0.985 (n=2). 두 row 가 같은 벡터를 저장한 상태 — argmin 판별 지표(acc)는 무의미.
A13: 시트 안내 | B13: 최종조건 · 손잡이효과 · MBL짝비교 · 조건별요약 · Rounds(전 라운드 원자료) · Cal_cells(라운드별 셀 교정값) · Best_round_points(최고 라운드 24질의 측정 vs 예측) · Best_round_curves(최고 라운드 1-D 교정 곡선) · Campaign_0905(전날 캠페인 2회 스캔·run) · Zero_0905(영점 결과)
A14: 원본 파일 | B14: meas_result/arrnight_rounds_chipX_arrnight_0906_095932.csv, arrnight_points_*, arrnight_cal_*, arrnight_curves_*, arrnight_opt_*.json, arrdist_status_chipX_arrdist_0905_145957/164533.json, arrauto_status_chipX_arrauto_0905_133125.json
A15: 스크립트 | B15: fefet_array.py (기반) · fefet_array_zero.py (영점) · fefet_array_distance.py (distance, v3 = 최종 조건 기본값) · fefet_array_night.py (조건 최적화, ctrl json 으로 조종)

Sheet 최종조건
A1: 최종 권장 읽기 조건 (0906 최적화)
A3: 항목 | B3: 값 | C3: 근거 (손잡이효과 / MBL짝비교 시트 참조)
A4: READ_V (MBL) [V] | B4: -1.75 | C4: 짝 비교 4블록 중앙값: −1.25 0.980 / −1.5 0.983 / −1.75 0.986 / −2.0 0.974. κ ∝ Vds (186→226 code/V²). −2.0 은 noise 10~11 로 상승, headroom 670. 스트레스 우려 시 −1.5 (−0.003).
A5: 게이트 중심 C [V] | B5: -0.93 | C5: Vth_mean(−1.43) + 0.5. ±0.1 오프셋 모두 손해 (0.912 / 0.942 vs 0.975).
A6: 질의 span ±[V] | B6: 0.7 | C6: R² 0.84(0.4) 0.88(0.5) 0.95(0.6) 0.977(0.7) 0.979(0.75). 0.75 는 이득 없음. 스윕 창 ≥ span 필수 (0.75 를 0.7 창으로 재면 0.84 로 붕괴).
A7: 교정 스윕 창 ±[V] | B7: 0.7 | C7: 질의 범위를 덮어야 곡선 예측·재중심이 됨. 0.8 은 동급 (0.98) 이나 시간 ↑.
A8: 2차 fit 창 ±[V] | B8: 0.6 | C8: 0.5 → 0.6 이 +0.02 (0.961 → 0.980 @span0.7). 0.7 은 동급 (0.981).
A9: samples (질의당) | B9: 3 | C9: 1: 0.948 (RMSE 10~12) · 3: 0.980 · 6: 0.985 (n=2, 질의 시간 +40%, 교정 시간 대비 미미).
A10: 질의 수 / 라운드 | B10: 24 | C10: 무작위 균일 (seed 고정 → 조건 간 짝 비교).
A11: 라운드 시간 [s] | B11: 131.25 | C11: 중앙값 (health + 교정 2열 + 24 질의). 교정 ≈ 99 s.
A14: 권장 조건에서의 성능 (Rounds 시트에서 수식으로 집계: span 0.7 / mbl −1.75 / sweep 0.7 / fit 0.6 / samples 3 / center_d 0)
A15: 지표 | B15: 값 | C15: 설명
A16: n (라운드 수) | B16: =COUNTIFS(Rounds!$E:$E,0.7,Rounds!$F:$F,-1.75,Rounds!$I:$I,0.7,Rounds!$J:$J,0.6,Rounds!$K:$K,3,Rounds!$H:$H,0) -> 13 | C16: Rounds 시트 COUNTIFS/AVERAGEIFS/MINIFS/MAXIFS
A17: score 평균 (row 평균 R²) | B17: =AVERAGEIFS(Rounds!$O:$O,Rounds!$E:$E,0.7,Rounds!$F:$F,-1.75,Rounds!$I:$I,0.7,Rounds!$J:$J,0.6,Rounds!$K:$K,3,Rounds!$H:$H,0) -> 0.98103077 | C17: Rounds 시트 COUNTIFS/AVERAGEIFS/MINIFS/MAXIFS
A18: score 최소 | B18: =_xlfn.MINIFS(Rounds!$O:$O,Rounds!$E:$E,0.7,Rounds!$F:$F,-1.75,Rounds!$I:$I,0.7,Rounds!$J:$J,0.6,Rounds!$K:$K,3,Rounds!$H:$H,0) -> 0.9722 | C18: Rounds 시트 COUNTIFS/AVERAGEIFS/MINIFS/MAXIFS
A19: score 최대 | B19: =_xlfn.MAXIFS(Rounds!$O:$O,Rounds!$E:$E,0.7,Rounds!$F:$F,-1.75,Rounds!$I:$I,0.7,Rounds!$J:$J,0.6,Rounds!$K:$K,3,Rounds!$H:$H,0) -> 0.9902 | C19: Rounds 시트 COUNTIFS/AVERAGEIFS/MINIFS/MAXIFS
A20: 2차 RMSE 평균 [code] | B20: =AVERAGEIFS(Rounds!$U:$U,Rounds!$E:$E,0.7,Rounds!$F:$F,-1.75,Rounds!$I:$I,0.7,Rounds!$J:$J,0.6,Rounds!$K:$K,3,Rounds!$H:$H,0) -> 6.2384615 | C20: Rounds 시트 COUNTIFS/AVERAGEIFS/MINIFS/MAXIFS
A21: noise 평균 [code] | B21: =AVERAGEIFS(Rounds!$AE:$AE,Rounds!$E:$E,0.7,Rounds!$F:$F,-1.75,Rounds!$I:$I,0.7,Rounds!$J:$J,0.6,Rounds!$K:$K,3,Rounds!$H:$H,0) -> 9.3 | C21: Rounds 시트 COUNTIFS/AVERAGEIFS/MINIFS/MAXIFS
A22: SNR 평균 | B22: =AVERAGEIFS(Rounds!$AC:$AC,Rounds!$E:$E,0.7,Rounds!$F:$F,-1.75,Rounds!$I:$I,0.7,Rounds!$J:$J,0.6,Rounds!$K:$K,3,Rounds!$H:$H,0) -> 7.7207692 | C22: Rounds 시트 COUNTIFS/AVERAGEIFS/MINIFS/MAXIFS
A23: 신호 σ 평균 [code] | B23: =AVERAGEIFS(Rounds!$AD:$AD,Rounds!$E:$E,0.7,Rounds!$F:$F,-1.75,Rounds!$I:$I,0.7,Rounds!$J:$J,0.6,Rounds!$K:$K,3,Rounds!$H:$H,0) -> 46.984615 | C23: Rounds 시트 COUNTIFS/AVERAGEIFS/MINIFS/MAXIFS
A24: κ 평균 [code/V²] | B24: =AVERAGEIFS(Rounds!$AK:$AK,Rounds!$E:$E,0.7,Rounds!$F:$F,-1.75,Rounds!$I:$I,0.7,Rounds!$J:$J,0.6,Rounds!$K:$K,3,Rounds!$H:$H,0) -> 226.53846 | C24: Rounds 시트 COUNTIFS/AVERAGEIFS/MINIFS/MAXIFS
A25: headroom 최소 [code] | B25: =_xlfn.MINIFS(Rounds!$AJ:$AJ,Rounds!$E:$E,0.7,Rounds!$F:$F,-1.75,Rounds!$I:$I,0.7,Rounds!$J:$J,0.6,Rounds!$K:$K,3,Rounds!$H:$H,0) -> 1255 | C25: Rounds 시트 COUNTIFS/AVERAGEIFS/MINIFS/MAXIFS
A26: depth 평균 [code] | B26: =AVERAGEIFS(Rounds!$AI:$AI,Rounds!$E:$E,0.7,Rounds!$F:$F,-1.75,Rounds!$I:$I,0.7,Rounds!$J:$J,0.6,Rounds!$K:$K,3,Rounds!$H:$H,0) -> 137.61538 | C26: Rounds 시트 COUNTIFS/AVERAGEIFS/MINIFS/MAXIFS
A28: ※ 중앙값은 엑셀 조건부 MEDIAN 이 배열수식이라 조건별요약 시트에 값으로 기록

Sheet Rounds
A1: round | B1: time | C1: phase | D1: tag | E1: span | F1: mbl | G1: center | H1: center_d | I1: sweep_half | J1: fit_half | K1: samples | L1: n_query | M1: seed | N1: is_ref | O1: score | P1: predictor | Q1: r2_q_row0 | R1: r2_q_row1 | S1: r2_q_rows | T1: r2_q_all | U1: rmse_q | V1: r2_c_row0 | W1: r2_c_row1 | X1: r2_c_rows | Y1: r2_c_all | Z1: rmse_c | AA1: n_sup | AB1: coverage | AC1: snr | AD1: sig_std | AE1: noise | AF1: resid_slope | AG1: acc_cal | AH1: margin | AI1: depth_min | AJ1: headroom_min | AK1: kappa_mean | AL1: S_check_max | AM1: m0_check_max | AN1: v0_R0C0 | AO1: v0_R0C1 | AP1: v0_R1C0 | AQ1: v0_R1C1 | AR1: se_max_mV | AS1: health_spread0 | AT1: health_spread1 | AU1: readout_flag | AV1: cal_s | AW1: run_s | AX1: t_s | AY1: timestamp
A2: 1 | B2: 09:59:39 | C2: queue | D2: base | E2: 0.5 | F2: -1.25 | G2: -0.93 | H2: 0 | I2: 0.5 | J2: 0.5 | K2: 3 | L2: 24 | M2: 20260905 | N2: 0 | O2: 0.7271 | P2: quad | Q2: 0.755 | R2: 0.699 | S2: 0.727 | T2: 0.959 | U2: 11.3 | V2: 0.185 | W2: 0.61 | X2: 0.398 | Y2: 0.937 | Z2: 13.7 | AA2: 46 | AB2: 0.96 | AC2: 1.97 | AD2: 22.3 | AE2: 11.7 | AF2: -0.034 | AG2: 0.33 | AH2: 9.4 | AI2: 64 | AJ2: 2147 | AK2: 186 | AL2: 15 | AM2: 19 | AN2: -0.0409 | AO2: 0.0351 | AP2: -0.0811 | AQ2: -0.0116 | AR2: 25 | AS2: 10 | AT2: 9 | AU2: 0 | AV2: 77 | AW2: 16.3 | AX2: 155.6 | AY2: 2026-09-06T09:59:39
A3: 2 | B3: 10:02:15 | C3: queue | D3: wide-sweep | E3: 0.6 | F3: -1.25 | G3: -0.93 | H3: 0 | I3: 0.7 | J3: 0.5 | K3: 3 | L3: 24 | M3: 20260905 | N3: 0 | O3: 0.924 | P3: quad | Q3: 0.915 | R3: 0.933 | S3: 0.924 | T3: 0.981 | U3: 8.3 | V3: 0.676 | W3: 0.801 | X3: 0.738 | Y3: 0.935 | Z3: 15.5 | AA3: 48 | AB3: 1 | AC3: 3.93 | AD3: 32.7 | AE3: 9.1 | AF3: -0.009 | AG3: 0.46 | AH3: 7.2 | AI3: 134 | AJ3: 2089 | AK3: 195 | AL3: 1 | AM3: 19 | AN3: -0.0268 | AO3: 0.0639 | AP3: -0.0319 | AQ3: 0.009 | AR3: 24 | AS3: 20 | AT3: 24 | AU3: 0 | AV3: 138 | AW3: 16 | AX3: 277.1 | AY3: 2026-09-06T10:02:15
A4: 3 | B4: 10:06:52 | C4: queue | D4: wide-sweep | E4: 0.7 | F4: -1.25 | G4: -0.93 | H4: 0 | I4: 0.7 | J4: 0.5 | K4: 3 | L4: 24 | M4: 20260905 | N4: 0 | O4: 0.9632 | P4: quad | Q4: 0.97 | R4: 0.957 | S4: 0.963 | T4: 0.987 | U4: 7.8 | V4: 0.919 | W4: 0.932 | X4: 0.925 | Y4: 0.972 | Z4: 11.2 | AA4: 46 | AB4: 0.96 | AC4: 5.26 | AD4: 41.1 | AE4: 8.9 | AF4: 0.037 | AG4: 0.58 | AH4: 6.4 | AI4: 119 | AJ4: 2100 | AK4: 191 | AL4: 1 | AM4: 1 | AN4: -0.047 | AO4: 0.0377 | AP4: -0.0508 | AQ4: 0.0431 | AR4: 17 | AS4: 15 | AT4: 18 | AU4: 0 | AV4: 94 | AW4: 15.4 | AX4: 110.1 | AY4: 2026-09-06T10:06:52
A5: 4 | B5: 10:08:42 | C5: queue | D5: mbl | E5: 0.5 | F5: -1.5 | G5: -0.93 | H5: 0 | I5: 0.5 | J5: 0.5 | K5: 3 | L5: 24 | M5: 20260905 | N5: 0 | O5: 0.8835 | P5: quad | Q5: 0.911 | R5: 0.856 | S5: 0.883 | T5: 0.984 | U5: 7.6 | V5: 0.167 | W5: 0.562 | X5: 0.365 | Y5: 0.934 | Z5: 14.7 | AA5: 44 | AB5: 0.92 | AC5: 2.84 | AD5: 21.5 | AE5: 10.3 | AF5: -0.012 | AG5: 0.67 | AH5: 8.4 | AI5: 84 | AJ5: 1784 | AK5: 195 | AL5: 1 | AM5: 7 | AN5: -0.0659 | AO5: 0.0544 | AP5: -0.0623 | AQ5: 0.0474 | AR5: 32 | AS5: 23 | AT5: 21 | AU5: 0 | AV5: 103 | AW5: 15.5 | AX5: 180.5 | AY5: 2026-09-06T10:08:42
A6: 5 | B6: 10:11:42 | C6: queue | D6: mbl | E6: 0.6 | F6: -1.5 | G6: -0.93 | H6: 0 | I6: 0.7 | J6: 0.5 | K6: 3 | L6: 24 | M6: 20260905 | N6: 0 | O6: 0.9317 | P6: quad | Q6: 0.937 | R6: 0.927 | S6: 0.932 | T6: 0.983 | U6: 8.6 | V6: 0.873 | W6: 0.868 | X6: 0.871 | Y6: 0.968 | Z6: 11.8 | AA6: 48 | AB6: 1 | AC6: 3.86 | AD6: 33.1 | AE6: 11.4 | AF6: 0.005 | AG6: 0.5 | AH6: 9 | AI6: 134 | AJ6: 1722 | AK6: 206 | AL6: 6 | AM6: 7 | AN6: -0.0513 | AO6: 0.0503 | AP6: -0.0471 | AQ6: 0.072 | AR6: 31 | AS6: 29 | AT6: 21 | AU6: 0 | AV6: 103 | AW6: 15.4 | AX6: 119.4 | AY6: 2026-09-06T10:11:42
A7: 6 | B7: 10:13:42 | C7: queue | D7: center | E7: 0.5 | F7: -1.25 | G7: -1.13 | H7: -0.2 | I7: 0.5 | J7: 0.5 | K7: 3 | L7: 24 | M7: 20260905 | N7: 0 | O7: 0.8515 | P7: quad | Q7: 0.762 | R7: 0.941 | S7: 0.851 | T7: 0.983 | U7: 7.5 | V7: 0.411 | W7: 0.722 | X7: 0.567 | Y7: 0.96 | Z7: 11.1 | AA7: 38 | AB7: 0.79 | AC7: 2.93 | AD7: 22.1 | AE7: 8.9 | AF7: 0.011 | AG7: 0.46 | AH7: 6.2 | AI7: 64 | AJ7: 2292 | AK7: 193 | AL7: 3 | AM7: 11 | AN7: -0.024 | AO7: 0.023 | AP7: -0.0348 | AQ7: -0.0105 | AR7: 22 | AS7: 24 | AT7: 20 | AU7: 0 | AV7: 103 | AW7: 15.9 | AX7: 181.2 | AY7: 2026-09-06T10:13:42
A8: 7 | B8: 10:16:43 | C8: queue | D8: center | E8: 0.5 | F8: -1.25 | G8: -0.83 | H8: 0.1 | I8: 0.5 | J8: 0.5 | K8: 3 | L8: 24 | M8: 20260905 | N8: 0 | O8: 0.8825 | P8: quad | Q8: 0.918 | R8: 0.847 | S8: 0.882 | T8: 0.982 | U8: 7.9 | V8: 0.4 | W8: 0.623 | X8: 0.512 | Y8: 0.925 | Z8: 15.9 | AA8: 48 | AB8: 1 | AC8: 2.63 | AD8: 20.6 | AE8: 10.6 | AF8: -0.003 | AG8: 0.71 | AH8: 9.7 | AI8: 57 | AJ8: 2075 | AK8: 183 | AL8: 2 | AM8: 16 | AN8: -0.0411 | AO8: 0.0466 | AP8: -0.0437 | AQ8: 0.0188 | AR8: 31 | AS8: 15 | AT8: 28 | AU8: 0 | AV8: 86 | AW8: 15.4 | AX8: 164 | AY8: 2026-09-06T10:16:43
A9: 8 | B9: 10:19:27 | C9: queue | D9: fit | E9: 0.5 | F9: -1.25 | G9: -0.93 | H9: 0 | I9: 0.5 | J9: 0.4 | K9: 3 | L9: 24 | M9: 20260905 | N9: 0 | O9: 0.8765 | P9: quad | Q9: 0.84 | R9: 0.913 | S9: 0.877 | T9: 0.983 | U9: 7.5 | V9: 0.697 | W9: 0.639 | X9: 0.668 | Y9: 0.963 | Z9: 10.7 | AA9: 46 | AB9: 0.96 | AC9: 2.89 | AD9: 21.8 | AE9: 12 | AF9: -0.013 | AG9: 0.5 | AH9: 9.9 | AI9: 52 | AJ9: 2137 | AK9: 191 | AL9: 5 | AM9: 17 | AN9: -0.0224 | AO9: 0.0543 | AP9: -0.0505 | AQ9: 0.0382 | AR9: 46 | AS9: 25 | AT9: 15 | AU9: 0 | AV9: 50 | AW9: 15.3 | AX9: 67 | AY9: 2026-09-06T10:19:27
A10: 9 | B10: 10:20:34 | C10: queue | D10: fit | E10: 0.5 | F10: -1.25 | G10: -0.93 | H10: 0 | I10: 0.6 | J10: 0.6 | K10: 3 | L10: 24 | M10: 20260905 | N10: 0 | O10: 0.8631 | P10: quad | Q10: 0.851 | R10: 0.875 | S10: 0.863 | T10: 0.981 | U10: 8 | V10: 0.83 | W10: 0.542 | X10: 0.686 | Y10: 0.956 | Z10: 12.1 | AA10: 48 | AB10: 1 | AC10: 2.74 | AD10: 22 | AE10: 9.5 | AF10: -0.007 | AG10: 0.5 | AH10: 8.1 | AI10: 76 | AJ10: 2151 | AK10: 196 | AL10: 1 | AM10: 22 | AN10: -0.0601 | AO10: 0.0433 | AP10: -0.0448 | AQ10: 0.0282 | AR10: 14 | AS10: 6 | AT10: 15 | AU10: 0 | AV10: 83 | AW10: 15.1 | AX10: 282.4 | AY10: 2026-09-06T10:20:34
A11: 10 | B11: 10:25:17 | C11: queue | D11: mbl | E11: 0.5 | F11: -1 | G11: -0.93 | H11: 0 | I11: 0.5 | J11: 0.5 | K11: 3 | L11: 24 | M11: 20260905 | N11: 0 | O11: 0.7624 | P11: quad | Q11: 0.682 | R11: 0.843 | S11: 0.762 | T11: 0.973 | U11: 9.3 | V11: 0.292 | W11: 0.599 | X11: 0.446 | Y11: 0.936 | Z11: 14.3 | AA11: 48 | AB11: 1 | AC11: 2.05 | AD11: 19.1 | AE11: 9.7 | AF11: 0.055 | AG11: 0.5 | AH11: 9.6 | AI11: 62 | AJ11: 2418 | AK11: 171 | AL11: 8 | AM11: 13 | AN11: -0.0347 | AO11: 0.0042 | AP11: -0.0264 | AQ11: 0.0121 | AR11: 25 | AS11: 26 | AT11: 10 | AU11: 0 | AV11: 93 | AW11: 15.5 | AX11: 109.6 | AY11: 2026-09-06T10:25:17
A12: 11 | B12: 10:27:06 | C12: queue | D12: wide-sweep | E12: 0.75 | F12: -1.25 | G12: -0.93 | H12: 0 | I12: 0.8 | J12: 0.5 | K12: 3 | L12: 24 | M12: 20260905 | N12: 0 | O12: 0.9603 | P12: quad | Q12: 0.957 | R12: 0.964 | S12: 0.96 | T12: 0.983 | U12: 9.3 | V12: 0.893 | W12: 0.968 | X12: 0.93 | Y12: 0.97 | Z12: 12.2 | AA12: 48 | AB12: 1 | AC12: 5.25 | AD12: 48.7 | AE12: 10.6 | AF12: -0.009 | AG12: 0.58 | AH12: 5.6 | AI12: 147 | AJ12: 2060 | AK12: 194 | AL12: 2 | AM12: 2 | AN12: -0.0569 | AO12: 0.0438 | AP12: -0.0286 | AQ12: 0.0408 | AR12: 21 | AS12: 12 | AT12: 28 | AU12: 0 | AV12: 134 | AW12: 16.3 | AX12: 212.6 | AY12: 2026-09-06T10:27:06
A13: 12 | B13: 10:30:39 | C13: queue | D13: wide-sweep | E13: 0.7 | F13: -1.25 | G13: -0.93 | H13: 0 | I13: 0.7 | J13: 0.6 | K13: 3 | L13: 24 | M13: 20260905 | N13: 0 | O13: 0.9797 | P13: quad | Q13: 0.987 | R13: 0.972 | S13: 0.98 | T13: 0.993 | U13: 5.6 | V13: 0.914 | W13: 0.955 | X13: 0.934 | Y13: 0.977 | Z13: 10.1 | AA13: 46 | AB13: 0.96 | AC13: 7.15 | AD13: 39.8 | AE13: 7.9 | AF13: -0.004 | AG13: 0.58 | AH13: 4.7 | AI13: 120 | AJ13: 2081 | AK13: 184 | AL13: 1 | AM13: 12 | AN13: -0.0322 | AO13: 0.0369 | AP13: -0.0389 | AQ13: 0.0212 | AR13: 13 | AS13: 11 | AT13: 8 | AU13: 0 | AV13: 136 | AW13: 16.6 | AX13: 214.6 | AY13: 2026-09-06T10:30:39
A14: 13 | B14: 10:34:13 | C14: rep-inc | E14: 0.5 | F14: -1.25 | G14: -0.93 | H14: 0 | I14: 0.5 | J14: 0.5 | K14: 3 | L14: 24 | M14: 20260906 | N14: 0 | O14: 0.9431 | P14: quad | Q14: 0.942 | R14: 0.944 | S14: 0.943 | T14: 0.995 | U14: 4.1 | V14: 0.918 | W14: 0.864 | X14: 0.891 | Y14: 0.99 | Z14: 5.7 | AA14: 48 | AB14: 1 | AC14: 4.3 | AD14: 17.7 | AE14: 6.5 | AF14: -0.027 | AG14: 0.46 | AH14: 4.8 | AI14: 61 | AJ14: 2149 | AK14: 186 | AL14: 1 | AM14: 1 | AN14: -0.0514 | AO14: 0.0414 | AP14: -0.0512 | AQ14: 0.0253 | AR14: 13 | AS14: 15 | AT14: 14 | AU14: 0 | AV14: 77 | AW14: 15.8 | AX14: 93.8 | AY14: 2026-09-06T10:34:13
A15: 14 | B15: 10:35:47 | C15: neighbor | E15: 0.4 | F15: -1.25 | G15: -0.93 | H15: 0 | I15: 0.5 | J15: 0.5 | K15: 3 | L15: 24 | M15: 20260905 | N15: 0 | O15: 0.899 | P15: quad | Q15: 0.922 | R15: 0.876 | S15: 0.899 | T15: 0.994 | U15: 4.1 | V15: 0.69 | W15: 0.8 | X15: 0.745 | Y15: 0.985 | Z15: 6.7 | AA15: 48 | AB15: 1 | AC15: 3.22 | AD15: 13.3 | AE15: 7.1 | AF15: -0.006 | AG15: 0.58 | AH15: 4.9 | AI15: 63 | AJ15: 2162 | AK15: 185 | AL15: 2 | AM15: 13 | AN15: -0.0565 | AO15: 0.0555 | AP15: -0.0498 | AQ15: 0.0411 | AR15: 11 | AS15: 7 | AT15: 7 | AU15: 0 | AV15: 76 | AW15: 16.5 | AX15: 94 | AY15: 2026-09-06T10:35:47
A16: 15 | B16: 10:37:21 | C16: neighbor | E16: 0.6 | F16: -1.25 | G16: -0.93 | H16: 0 | I16: 0.5 | J16: 0.5 | K16: 3 | L16: 24 | M16: 20260905 | N16: 0 | O16: 0.9509 | P16: quad | Q16: 0.952 | R16: 0.95 | S16: 0.951 | T16: 0.989 | U16: 6.5 | V16: 0.792 | W16: 0.818 | X16: 0.805 | Y16: 0.973 | Z16: 9.5 | AA16: 38 | AB16: 0.79 | AC16: 4.96 | AD16: 32.3 | AE16: 7 | AF16: -0.033 | AG16: 0.67 | AH16: 5.3 | AI16: 67 | AJ16: 2143 | AK16: 195 | AL16: 4 | AM16: 4 | AN16: -0.0235 | AO16: 0.0493 | AP16: -0.0493 | AQ16: 0.0137 | AR16: 15 | AS16: 5 | AT16: 9 | AU16: 0 | AV16: 103 | AW16: 16.1 | AX16: 181.5 | AY16: 2026-09-06T10:37:21
A17: 16 | B17: 10:40:23 | C17: ref | E17: 0.5 | F17: -1.25 | G17: -0.93 | H17: 0 | I17: 0.5 | J17: 0.5 | K17: 3 | L17: 24 | M17: 20260907 | N17: 1 | O17: 0.8844 | P17: quad | Q17: 0.865 | R17: 0.903 | S17: 0.884 | T17: 0.985 | U17: 7 | V17: 0.8 | W17: 0.816 | X17: 0.808 | Y17: 0.975 | Z17: 9.1 | AA17: 48 | AB17: 1 | AC17: 3.4 | AD17: 23.9 | AE17: 7.5 | AF17: -0.009 | AG17: 0.67 | AH17: 6.2 | AI17: 65 | AJ17: 2147 | AK17: 202 | AL17: 4 | AM17: 9 | AN17: -0.0356 | AO17: 0.0426 | AP17: -0.0534 | AQ17: 0.0163 | AR17: 14 | AS17: 23 | AT17: 8 | AU17: 0 | AV17: 60 | AW17: 15.9 | AX17: 77.2 | AY17: 2026-09-06T10:40:23
A18: 17 | B18: 10:41:40 | C18: neighbor | E18: 0.5 | F18: -1.25 | G18: -0.93 | H18: 0 | I18: 0.6 | J18: 0.5 | K18: 3 | L18: 24 | M18: 20260905 | N18: 0 | O18: 0.8533 | P18: quad | Q18: 0.894 | R18: 0.813 | S18: 0.853 | T18: 0.981 | U18: 7.8 | V18: 0.807 | W18: 0.841 | X18: 0.824 | Y18: 0.977 | Z18: 8.7 | AA18: 48 | AB18: 1 | AC18: 2.85 | AD18: 22.3 | AE18: 5.9 | AF18: 0.007 | AG18: 0.5 | AH18: 5.7 | AI18: 90 | AJ18: 2125 | AK18: 201 | AL18: 6 | AM18: 6 | AN18: -0.0465 | AO18: 0.0318 | AP18: -0.0365 | AQ18: 0.0231 | AR18: 14 | AS18: 7 | AT18: 8 | AU18: 0 | AV18: 110 | AW18: 16.5 | AX18: 188.5 | AY18: 2026-09-06T10:41:40
A19: 18 | B19: 10:44:49 | C19: neighbor | E19: 0.5 | F19: -1.25 | G19: -1.03 | H19: -0.1 | I19: 0.5 | J19: 0.5 | K19: 3 | L19: 24 | M19: 20260905 | N19: 0 | O19: 0.8339 | P19: quad | Q19: 0.797 | R19: 0.87 | S19: 0.834 | T19: 0.978 | U19: 8.6 | V19: 0.612 | W19: 0.647 | X19: 0.629 | Y19: 0.95 | Z19: 12.9 | AA19: 48 | AB19: 1 | AC19: 2.31 | AD19: 19.9 | AE19: 8.5 | AF19: 0.022 | AG19: 0.71 | AH19: 5.1 | AI19: 58 | AJ19: 2252 | AK19: 173 | AL19: 7 | AM19: 9 | AN19: -0.0486 | AO19: 0.0672 | AP19: -0.0457 | AQ19: 0.0182 | AR19: 17 | AS19: 20 | AT19: 27 | AU19: 0 | AV19: 88 | AW19: 15.3 | AX19: 165.3 | AY19: 2026-09-06T10:44:49
A20: 19 | B20: 10:47:34 | C20: neighbor | E20: 0.5 | F20: -1.25 | G20: -0.93 | H20: 0 | I20: 0.6 | J20: 0.5 | K20: 3 | L20: 24 | M20: 20260906 | N20: 0 | O20: 0.9195 | P20: quad | Q20: 0.92 | R20: 0.919 | S20: 0.92 | T20: 0.991 | U20: 5.2 | V20: 0.795 | W20: 0.621 | X20: 0.708 | Y20: 0.968 | Z20: 9.9 | AA20: 48 | AB20: 1 | AC20: 3.64 | AD20: 18.8 | AE20: 8 | AF20: -0.03 | AG20: 0.58 | AH20: 5 | AI20: 77 | AJ20: 2119 | AK20: 194 | AL20: 5 | AM20: 12 | AN20: -0.0496 | AO20: 0.028 | AP20: -0.0695 | AQ20: 0.0395 | AR20: 15 | AS20: 8 | AT20: 8 | AU20: 0 | AV20: 121 | AW20: 17.1 | AX20: 138.9 | AY20: 2026-09-06T10:47:34
A21: 20 | B21: 10:49:53 | C21: ref | E21: 0.5 | F21: -1.25 | G21: -0.93 | H21: 0 | I21: 0.5 | J21: 0.5 | K21: 3 | L21: 24 | M21: 20260908 | N21: 1 | O21: 0.8401 | P21: quad | Q21: 0.845 | R21: 0.836 | S21: 0.84 | T21: 0.986 | U21: 6.7 | V21: 0.569 | W21: -0.232 | X21: 0.168 | Y21: 0.924 | Z21: 15.4 | AA21: 48 | AB21: 1 | AC21: 2.22 | AD21: 14.9 | AE21: 7.5 | AF21: -0.005 | AG21: 0.67 | AH21: 4.6 | AI21: 63 | AJ21: 2168 | AK21: 179 | AL21: 10 | AM21: 16 | AN21: -0.0559 | AO21: 0.0588 | AP21: -0.0497 | AQ21: 0.0486 | AR21: 14 | AS21: 14 | AT21: 15 | AU21: 0 | AV21: 76 | AW21: 15.8 | AX21: 92.7 | AY21: 2026-09-06T10:49:53
A22: 21 | B22: 10:51:30 | C22: neighbor | E22: 0.5 | F22: -1.25 | G22: -0.93 | H22: 0 | I22: 0.7 | J22: 0.5 | K22: 3 | L22: 24 | M22: 20260905 | N22: 0 | O22: 0.8069 | P22: quad | Q22: 0.746 | R22: 0.868 | S22: 0.807 | T22: 0.973 | U22: 9.6 | V22: 0.715 | W22: 0.838 | X22: 0.777 | Y22: 0.968 | Z22: 10.3 | AA22: 48 | AB22: 1 | AC22: 2.26 | AD22: 21.7 | AE22: 9.7 | AF22: 0.042 | AG22: 0.42 | AH22: 7.9 | AI22: 101 | AJ22: 2094 | AK22: 196 | AL22: 8 | AM22: 3 | AN22: -0.0488 | AO22: 0.0632 | AP22: -0.0498 | AQ22: 0.0486 | AR22: 19 | AS22: 6 | AT22: 18 | AU22: 0 | AV22: 134 | AW22: 15.8 | AX22: 211.7 | AY22: 2026-09-06T10:51:30
A23: 22 | B23: 10:55:02 | C23: neighbor | E23: 0.4 | F23: -1.25 | G23: -0.93 | H23: 0 | I23: 0.6 | J23: 0.5 | K23: 3 | L23: 24 | M23: 20260905 | N23: 0 | O23: 0.7791 | P23: quad | Q23: 0.662 | R23: 0.897 | S23: 0.779 | T23: 0.987 | U23: 6 | V23: 0.55 | W23: 0.774 | X23: 0.662 | Y23: 0.98 | Z23: 7.5 | AA23: 48 | AB23: 1 | AC23: 2.28 | AD23: 13.8 | AE23: 7.7 | AF23: -0.017 | AG23: 0.58 | AH23: 4.9 | AI23: 86 | AJ23: 2139 | AK23: 189 | AL23: 2 | AM23: 5 | AN23: -0.0321 | AO23: 0.0228 | AP23: -0.058 | AQ23: 0.0288 | AR23: 11 | AS23: 8 | AT23: 7 | AU23: 0 | AV23: 88 | AW23: 16.1 | AX23: 166.6 | AY23: 2026-09-06T10:55:02
A24: 23 | B24: 10:57:48 | C24: neighbor | E24: 0.5 | F24: -1 | G24: -0.93 | H24: 0 | I24: 0.6 | J24: 0.5 | K24: 3 | L24: 24 | M24: 20260905 | N24: 0 | O24: 0.8317 | P24: quad | Q24: 0.804 | R24: 0.859 | S24: 0.832 | T24: 0.978 | U24: 7.9 | V24: 0.69 | W24: 0.434 | X24: 0.562 | Y24: 0.947 | Z24: 12.3 | AA24: 48 | AB24: 1 | AC24: 1.98 | AD24: 15.5 | AE24: 8.3 | AF24: -0.005 | AG24: 0.42 | AH24: 7.6 | AI24: 79 | AJ24: 2402 | AK24: 139 | AL24: 9 | AM24: 7 | AN24: -0.018 | AO24: -0.0004 | AP24: -0.031 | AQ24: -0.0053 | AR24: 20 | AS24: 5 | AT24: 10 | AU24: 0 | AV24: 127 | AW24: 15.7 | AX24: 143.5 | AY24: 2026-09-06T10:57:48
A25: 24 | B25: 11:00:12 | C25: ref | E25: 0.5 | F25: -1.25 | G25: -0.93 | H25: 0 | I25: 0.6 | J25: 0.5 | K25: 3 | L25: 24 | M25: 20260907 | N25: 1 | O25: 0.944 | P25: quad | Q25: 0.947 | R25: 0.941 | S25: 0.944 | T25: 0.992 | U25: 5.2 | V25: 0.776 | W25: 0.681 | X25: 0.729 | Y25: 0.961 | Z25: 11.4 | AA25: 48 | AB25: 1 | AC25: 4.19 | AD25: 21.8 | AE25: 6.8 | AF25: 0.036 | AG25: 0.71 | AH25: 4.9 | AI25: 87 | AJ25: 2147 | AK25: 192 | AL25: 3 | AM25: 12 | AN25: -0.0518 | AO25: 0.0234 | AP25: -0.0536 | AQ25: 0.0273 | AR25: 16 | AS25: 15 | AT25: 15 | AU25: 0 | AV25: 70 | AW25: 15.6 | AX25: 86.7 | AY25: 2026-09-06T11:00:12
... A31: 30 | B31: 11:13:45 | C31: neighbor | E31: 0.5 | F31: -1.5 | G31: -0.93 | H31: 0 | I31: 0.6 | J31: 0.5 | K31: 3 | L31: 24 | M31: 20260905 | N31: 0 | O31: 0.9261 | P31: quad | Q31: 0.92 | R31: 0.932 | S31: 0.926 | T31: 0.989 | U31: 6.1 | V31: 0.836 | W31: 0.881 | X31: 0.859 | Y31: 0.98 | Z31: 8.4 | AA31: 48 | AB31: 1 | AC31: 4.16 | AD31: 25.3 | AE31: 8.1 | AF31: 0.004 | AG31: 0.71 | AH31: 5.6 | AI31: 86 | AJ31: 1795 | AK31: 223 | AL31: 5 | AM31: 12 | AN31: -0.0563 | AO31: 0.0856 | AP31: -0.0588 | AQ31: 0.0509 | AR31: 18 | AS31: 10 | AT31: 9 | AU31: 0 | AV31: 116 | AW31: 16.6 | AX31: 133.8 | AY31: 2026-09-06T11:13:45
A32: 31 | B32: 11:15:59 | C32: queue | D32: top-rep | E32: 0.7 | F32: -1.25 | G32: -0.93 | H32: 0 | I32: 0.7 | J32: 0.6 | K32: 3 | L32: 24 | M32: 20260906 | N32: 0 | O32: 0.9719 | P32: quad | Q32: 0.965 | R32: 0.978 | S32: 0.972 | T32: 0.992 | U32: 5.6 | V32: 0.9 | W32: 0.971 | X32: 0.935 | Y32: 0.981 | Z32: 8.7 | AA32: 46 | AB32: 0.96 | AC32: 6.23 | AD32: 35 | AE32: 7.3 | AF32: -0.015 | AG32: 0.62 | AH32: 5.6 | AI32: 96 | AJ32: 2115 | AK32: 186 | AL32: 4 | AM32: 2 | AN32: -0.038 | AO32: 0.0616 | AP32: -0.0515 | AQ32: 0.0334 | AR32: 10 | AS32: 11 | AT32: 20 | AU32: 0 | AV32: 94 | AW32: 16.2 | AX32: 111.7 | AY32: 2026-09-06T11:15:59
A33: 32 | B33: 11:17:51 | C33: queue | D33: top-rep | E33: 0.7 | F33: -1.25 | G33: -0.93 | H33: 0 | I33: 0.7 | J33: 0.6 | K33: 3 | L33: 24 | M33: 20260907 | N33: 0 | O33: 0.9808 | P33: quad | Q33: 0.975 | R33: 0.987 | S33: 0.981 | T33: 0.992 | U33: 5.9 | V33: 0.975 | W33: 0.979 | X33: 0.977 | Y33: 0.991 | Z33: 6.5 | AA33: 48 | AB33: 1 | AC33: 7.09 | AD33: 42.1 | AE33: 7 | AF33: 0.009 | AG33: 0.58 | AH33: 4.3 | AI33: 133 | AJ33: 2103 | AK33: 188 | AL33: 4 | AM33: 17 | AN33: -0.0578 | AO33: 0.0267 | AP33: -0.0431 | AQ33: 0.0234 | AR33: 9 | AS33: 24 | AT33: 22 | AU33: 0 | AV33: 77 | AW33: 15.9 | AX33: 93.6 | AY33: 2026-09-06T11:17:51
A34: 33 | B34: 11:19:24 | C34: queue | D34: top-rep | E34: 0.7 | F34: -1.25 | G34: -0.93 | H34: 0 | I34: 0.7 | J34: 0.5 | K34: 3 | L34: 24 | M34: 20260906 | N34: 0 | O34: 0.9592 | P34: quad | Q34: 0.97 | R34: 0.948 | S34: 0.959 | T34: 0.989 | U34: 6.9 | V34: 0.928 | W34: 0.92 | X34: 0.924 | Y34: 0.978 | Z34: 9.5 | AA34: 48 | AB34: 1 | AC34: 5.18 | AD34: 35.8 | AE34: 6.9 | AF34: -0.008 | AG34: 0.62 | AH34: 5.9 | AI34: 111 | AJ34: 2103 | AK34: 194 | AL34: 3 | AM34: 2 | AN34: -0.0439 | AO34: 0.0253 | AP34: -0.0551 | AQ34: 0.0154 | AR34: 15 | AS34: 8 | AT34: 19 | AU34: 0 | AV34: 97 | AW34: 15.7 | AX34: 114.4 | AY34: 2026-09-06T11:19:24
A35: 34 | B35: 11:21:19 | C35: queue | D35: top-rep | E35: 0.75 | F35: -1.25 | G35: -0.93 | H35: 0 | I35: 0.8 | J35: 0.5 | K35: 3 | L35: 24 | M35: 20260906 | N35: 0 | O35: 0.9463 | P35: quad | Q35: 0.926 | R35: 0.967 | S35: 0.946 | T35: 0.982 | U35: 8.9 | V35: 0.935 | W35: 0.94 | X35: 0.937 | Y35: 0.979 | Z35: 9.6 | AA35: 48 | AB35: 1 | AC35: 4.68 | AD35: 41.5 | AE35: 6.1 | AF35: 0.016 | AG35: 0.38 | AH35: 5.3 | AI35: 146 | AJ35: 2077 | AK35: 190 | AL35: 8 | AM35: 12 | AN35: -0.0571 | AO35: 0.0552 | AP35: -0.0702 | AQ35: 0.0286 | AR35: 16 | AS35: 18 | AT35: 25 | AU35: 0 | AV35: 113 | AW35: 16.2 | AX35: 130.1 | AY35: 2026-09-06T11:21:19
A36: 35 | B36: 11:23:29 | C36: queue | D36: new | E36: 0.75 | F36: -1.25 | G36: -0.93 | H36: 0 | I36: 0.8 | J36: 0.6 | K36: 3 | L36: 24 | M36: 20260905 | N36: 0 | O36: 0.9846 | P36: quad | Q36: 0.99 | R36: 0.979 | S36: 0.985 | T36: 0.994 | U36: 5.6 | V36: 0.894 | W36: 0.927 | X36: 0.91 | Y36: 0.97 | Z36: 11.4 | AA36: 46 | AB36: 0.96 | AC36: 8.63 | AD36: 48.4 | AE36: 9.1 | AF36: -0.019 | AG36: 0.54 | AH36: 4.6 | AI36: 162 | AJ36: 2068 | AK36: 194 | AL36: 2 | AM36: 9 | AN36: -0.0532 | AO36: 0.0539 | AP36: -0.0407 | AQ36: 0.0389 | AR36: 12 | AS36: 8 | AT36: 6 | AU36: 0 | AV36: 111 | AW36: 16.8 | AX36: 128.8 | AY36: 2026-09-06T11:23:29
A37: 36 | B37: 11:25:38 | C37: queue | D37: new | E37: 0.7 | F37: -1.25 | G37: -0.93 | H37: 0 | I37: 0.7 | J37: 0.7 | K37: 3 | L37: 24 | M37: 20260905 | N37: 0 | O37: 0.9796 | P37: quad | Q37: 0.98 | R37: 0.979 | S37: 0.98 | T37: 0.993 | U37: 6 | V37: 0.898 | W37: 0.954 | X37: 0.926 | Y37: 0.974 | Z37: 11.2 | AA37: 48 | AB37: 1 | AC37: 7.01 | AD37: 41.8 | AE37: 7.9 | AF37: 0.025 | AG37: 0.33 | AH37: 6.2 | AI37: 119 | AJ37: 2119 | AK37: 192 | AL37: 2 | AM37: 3 | AN37: -0.0571 | AO37: 0.0343 | AP37: -0.0392 | AQ37: 0.0427 | AR37: 9 | AS37: 22 | AT37: 11 | AU37: 0 | AV37: 118 | AW37: 16.9 | AX37: 197.4 | AY37: 2026-09-06T11:25:38
A38: 37 | B38: 11:28:55 | C38: queue | D38: new | E38: 0.7 | F38: -1.5 | G38: -0.93 | H38: 0 | I38: 0.7 | J38: 0.6 | K38: 3 | L38: 24 | M38: 20260905 | N38: 0 | O38: 0.98 | P38: quad | Q38: 0.983 | R38: 0.977 | S38: 0.98 | T38: 0.992 | U38: 6.2 | V38: 0.951 | W38: 0.948 | X38: 0.949 | Y38: 0.984 | Z38: 8.3 | AA38: 46 | AB38: 0.96 | AC38: 7.12 | AD38: 44.3 | AE38: 7.6 | AF38: -0.015 | AG38: 0.5 | AH38: 7 | AI38: 109 | AJ38: 1750 | AK38: 204 | AL38: 5 | AM38: 5 | AN38: -0.0548 | AO38: 0.0716 | AP38: -0.071 | AQ38: 0.0668 | AR38: 12 | AS38: 7 | AT38: 23 | AU38: 0 | AV38: 133 | AW38: 15.5 | AX38: 272.5 | AY38: 2026-09-06T11:28:55
A39: 38 | B39: 11:33:28 | C39: queue | D39: top-rep | E39: 0.6 | F39: -1.25 | G39: -0.93 | H39: 0 | I39: 0.6 | J39: 0.5 | K39: 3 | L39: 24 | M39: 20260906 | N39: 0 | O39: 0.9358 | P39: quad | Q39: 0.939 | R39: 0.933 | S39: 0.936 | T39: 0.988 | U39: 6.4 | V39: 0.944 | W39: 0.848 | X39: 0.896 | Y39: 0.981 | Z39: 8.2 | AA39: 48 | AB39: 1 | AC39: 4.01 | AD39: 25.8 | AE39: 7.4 | AF39: 0.011 | AG39: 0.62 | AH39: 5.5 | AI39: 85 | AJ39: 2138 | AK39: 191 | AL39: 5 | AM39: 3 | AN39: -0.0683 | AO39: 0.0452 | AP39: -0.0609 | AQ39: 0.0432 | AR39: 12 | AS39: 14 | AT39: 9 | AU39: 0 | AV39: 76 | AW39: 16.3 | AX39: 93.5 | AY39: 2026-09-06T11:33:28
A40: 39 | B40: 11:35:01 | C40: queue | D40: new | E40: 0.7 | F40: -1.25 | G40: -0.93 | H40: 0 | I40: 0.8 | J40: 0.6 | K40: 3 | L40: 24 | M40: 20260905 | N40: 0 | O40: 0.9785 | P40: quad | Q40: 0.988 | R40: 0.969 | S40: 0.978 | T40: 0.993 | U40: 5.7 | V40: 0.971 | W40: 0.956 | X40: 0.964 | Y40: 0.987 | Z40: 7.4 | AA40: 48 | AB40: 1 | AC40: 7.2 | AD40: 40.8 | AE40: 6.5 | AF40: -0.029 | AG40: 0.54 | AH40: 5.2 | AI40: 146 | AJ40: 2067 | AK40: 187 | AL40: 2 | AM40: 12 | AN40: -0.0412 | AO40: 0.0353 | AP40: -0.0506 | AQ40: 0.055 | AR40: 11 | AS40: 25 | AT40: 25 | AU40: 0 | AV40: 85 | AW40: 15.4 | AX40: 102 | AY40: 2026-09-06T11:35:01
A41: 40 | B41: 11:36:43 | C41: ref | E41: 0.7 | F41: -1.25 | G41: -0.93 | H41: 0 | I41: 0.7 | J41: 0.6 | K41: 3 | L41: 24 | M41: 20260908 | N41: 1 | O41: 0.9445 | P41: quad | Q41: 0.968 | R41: 0.921 | S41: 0.944 | T41: 0.986 | U41: 7.3 | V41: 0.966 | W41: 0.852 | X41: 0.909 | Y41: 0.976 | Z41: 9.6 | AA41: 46 | AB41: 0.96 | AC41: 3.97 | AD41: 29 | AE41: 8.9 | AF41: 0.037 | AG41: 0.58 | AH41: 6.8 | AI41: 115 | AJ41: 2106 | AK41: 180 | AL41: 2 | AM41: 6 | AN41: -0.0424 | AO41: 0.0553 | AP41: -0.0359 | AQ41: 0.0458 | AR41: 15 | AS41: 9 | AT41: 18 | AU41: 0 | AV41: 136 | AW41: 15.9 | AX41: 336.7 | AY41: 2026-09-06T11:36:43
A42: 41 | B42: 11:42:24 | C42: neighbor | E42: 0.6 | F42: -1.25 | G42: -0.93 | H42: 0 | I42: 0.7 | J42: 0.6 | K42: 3 | L42: 24 | M42: 20260905 | N42: 0 | O42: 0.9521 | P42: quad | Q42: 0.967 | R42: 0.938 | S42: 0.952 | T42: 0.988 | U42: 6.7 | V42: 0.897 | W42: 0.888 | X42: 0.893 | Y42: 0.973 | Z42: 10 | AA42: 48 | AB42: 1 | AC42: 4.28 | AD42: 28.9 | AE42: 9.7 | AF42: 0.016 | AG42: 0.62 | AH42: 7.6 | AI42: 95 | AJ42: 2144 | AK42: 181 | AL42: 6 | AM42: 7 | AN42: -0.0431 | AO42: 0.0415 | AP42: -0.0536 | AQ42: 0.0494 | AR42: 15 | AS42: 13 | AT42: 6 | AU42: 0 | AV42: 133 | AW42: 16.1 | AX42: 210.7 | AY42: 2026-09-06T11:42:24
A43: 42 | B43: 11:45:55 | C43: neighbor | E43: 0.7 | F43: -1.25 | G43: -1.03 | H43: -0.1 | I43: 0.7 | J43: 0.6 | K43: 3 | L43: 24 | M43: 20260905 | N43: 0 | O43: 0.9618 | P43: quad | Q43: 0.966 | R43: 0.958 | S43: 0.962 | T43: 0.987 | U43: 7.4 | V43: 0.933 | W43: 0.948 | X43: 0.941 | Y43: 0.98 | Z43: 9.3 | AA43: 46 | AB43: 0.96 | AC43: 5.35 | AD43: 39.7 | AE43: 8.1 | AF43: 0 | AG43: 0.67 | AH43: 9 | AI43: 112 | AJ43: 2199 | AK43: 182 | AL43: 4 | AM43: 10 | AN43: -0.0374 | AO43: 0.0443 | AP43: -0.0319 | AQ43: 0.023 | AR43: 10 | AS43: 11 | AT43: 10 | AU43: 0 | AV43: 116 | AW43: 15.8 | AX43: 315.8 | AY43: 2026-09-06T11:45:55
A44: 43 | B44: 11:51:11 | C44: neighbor | E44: 0.7 | F44: -1.25 | G44: -0.93 | H44: 0 | I44: 0.6 | J44: 0.6 | K44: 3 | L44: 24 | M44: 20260905 | N44: 0 | O44: 0.9726 | P44: quad | Q44: 0.977 | R44: 0.968 | S44: 0.973 | T44: 0.989 | U44: 6.9 | V44: 0.937 | W44: 0.955 | X44: 0.946 | Y44: 0.984 | Z44: 8.1 | AA44: 44 | AB44: 0.92 | AC44: 5.82 | AD44: 40.4 | AE44: 6.6 | AF44: 0.027 | AG44: 0.5 | AH44: 4.9 | AI44: 83 | AJ44: 2149 | AK44: 185 | AL44: 8 | AM44: 6 | AN44: -0.055 | AO44: 0.0367 | AP44: -0.0389 | AQ44: 0.0227 | AR44: 11 | AS44: 21 | AT44: 9 | AU44: 0 | AV44: 69 | AW44: 15.9 | AX44: 85.7 | AY44: 2026-09-06T11:51:11
A45: 44 | B45: 11:52:37 | C45: ref | E45: 0.7 | F45: -1.25 | G45: -0.93 | H45: 0 | I45: 0.7 | J45: 0.6 | K45: 3 | L45: 24 | M45: 20260909 | N45: 1 | O45: 0.971 | P45: quad | Q45: 0.97 | R45: 0.972 | S45: 0.971 | T45: 0.989 | U45: 7.2 | V45: 0.917 | W45: 0.928 | X45: 0.923 | Y45: 0.971 | Z45: 11.7 | AA45: 48 | AB45: 1 | AC45: 5.8 | AD45: 41.6 | AE45: 10.1 | AF45: 0.018 | AG45: 0.67 | AH45: 8.1 | AI45: 103 | AJ45: 2092 | AK45: 186 | AL45: 5 | AM45: 9 | AN45: -0.0385 | AO45: 0.0502 | AP45: -0.074 | AQ45: 0.0385 | AR45: 17 | AS45: 11 | AT45: 7 | AU45: 0 | AV45: 112 | AW45: 16 | AX45: 129 | AY45: 2026-09-06T11:52:37
...

Sheet 손잡이효과
A1: 손잡이별 효과 — 전체 138 라운드 (n, 평균: 수식 / 중앙값·최소·최대: 값)
A2: 주의: 조건이 섞여 있는 주변 분포(marginal). 손잡이 하나의 순수 효과는 아래 "고정 조건" 표와 MBL짝비교 시트를 볼 것.
A4: span
A5: 값 | B5: n | C5: 평균 | D5: 중앙값 | E5: 최소 | F5: 최대 | G5: 평균 RMSE | H5: 메모
A6: 0.4 | B6: =COUNTIFS(Rounds!$E:$E,A6) -> 2 | C6: =AVERAGEIFS(Rounds!$O:$O,Rounds!$E:$E,A6) -> 0.83905 | D6: 0.83905 | E6: 0.7791 | F6: 0.899 | G6: =AVERAGEIFS(Rounds!$U:$U,Rounds!$E:$E,A6) -> 5.05
A7: 0.5 | B7: =COUNTIFS(Rounds!$E:$E,A7) -> 21 | C7: =AVERAGEIFS(Rounds!$O:$O,Rounds!$E:$E,A7) -> 0.86746667 | D7: 0.8765 | E7: 0.7271 | F7: 0.944 | G7: =AVERAGEIFS(Rounds!$U:$U,Rounds!$E:$E,A7) -> 7.2714286
A8: 0.6 | B8: =COUNTIFS(Rounds!$E:$E,A8) -> 11 | C8: =AVERAGEIFS(Rounds!$O:$O,Rounds!$E:$E,A8) -> 0.95258182 | D8: 0.9509 | E8: 0.924 | F8: 0.9808 | G8: =AVERAGEIFS(Rounds!$U:$U,Rounds!$E:$E,A8) -> 6.2636364
A9: 0.7 | B9: =COUNTIFS(Rounds!$E:$E,A9) -> 83 | C9: =AVERAGEIFS(Rounds!$O:$O,Rounds!$E:$E,A9) -> 0.97215904 | D9: 0.9771 | E9: 0.9057 | F9: 0.9902 | G9: =AVERAGEIFS(Rounds!$U:$U,Rounds!$E:$E,A9) -> 6.8240964
A10: 0.75 | B10: =COUNTIFS(Rounds!$E:$E,A10) -> 21 | C10: =AVERAGEIFS(Rounds!$O:$O,Rounds!$E:$E,A10) -> 0.96656667 | D10: 0.9792 | E10: 0.8394 | F10: 0.9877 | G10: =AVERAGEIFS(Rounds!$U:$U,Rounds!$E:$E,A10) -> 7.6666667
A12: mbl
A13: 값 | B13: n | C13: 평균 | D13: 중앙값 | E13: 최소 | F13: 최대 | G13: 평균 RMSE | H13: 메모
A14: -2 | B14: =COUNTIFS(Rounds!$F:$F,A14) -> 13 | C14: =AVERAGEIFS(Rounds!$O:$O,Rounds!$F:$F,A14) -> 0.96973077 | D14: 0.9809 | E14: 0.925 | F14: 0.9871 | G14: =AVERAGEIFS(Rounds!$U:$U,Rounds!$F:$F,A14) -> 7.8769231
A15: -1.75 | B15: =COUNTIFS(Rounds!$F:$F,A15) -> 34 | C15: =AVERAGEIFS(Rounds!$O:$O,Rounds!$F:$F,A15) -> 0.97474118 | D15: 0.9797 | E15: 0.9164 | F15: 0.9902 | G15: =AVERAGEIFS(Rounds!$U:$U,Rounds!$F:$F,A15) -> 7.0588235
A16: -1.5 | B16: =COUNTIFS(Rounds!$F:$F,A16) -> 20 | C16: =AVERAGEIFS(Rounds!$O:$O,Rounds!$F:$F,A16) -> 0.965195 | D16: 0.97855 | E16: 0.8835 | F16: 0.9891 | G16: =AVERAGEIFS(Rounds!$U:$U,Rounds!$F:$F,A16) -> 6.57
A17: -1.25 | B17: =COUNTIFS(Rounds!$F:$F,A17) -> 69 | C17: =AVERAGEIFS(Rounds!$O:$O,Rounds!$F:$F,A17) -> 0.9378942 | D17: 0.9603 | E17: 0.7271 | F17: 0.9873 | G17: =AVERAGEIFS(Rounds!$U:$U,Rounds!$F:$F,A17) -> 6.784058
A18: -1 | B18: =COUNTIFS(Rounds!$F:$F,A18) -> 2 | C18: =AVERAGEIFS(Rounds!$O:$O,Rounds!$F:$F,A18) -> 0.79705 | D18: 0.79705 | E18: 0.7624 | F18: 0.8317 | G18: =AVERAGEIFS(Rounds!$U:$U,Rounds!$F:$F,A18) -> 8.6
A20: center_d
A21: 값 | B21: n | C21: 평균 | D21: 중앙값 | E21: 최소 | F21: 최대 | G21: 평균 RMSE | H21: 메모
A22: -0.2 | B22: =COUNTIFS(Rounds!$H:$H,A22) -> 1 | C22: =AVERAGEIFS(Rounds!$O:$O,Rounds!$H:$H,A22) -> 0.8515 | D22: 0.8515 | E22: 0.8515 | F22: 0.8515 | G22: =AVERAGEIFS(Rounds!$U:$U,Rounds!$H:$H,A22) -> 7.5
A23: -0.1 | B23: =COUNTIFS(Rounds!$H:$H,A23) -> 3 | C23: =AVERAGEIFS(Rounds!$O:$O,Rounds!$H:$H,A23) -> 0.90243333 | D23: 0.9116 | E23: 0.8339 | F23: 0.9618 | G23: =AVERAGEIFS(Rounds!$U:$U,Rounds!$H:$H,A23) -> 7.3
A24: 0 | B24: =COUNTIFS(Rounds!$H:$H,A24) -> 131 | C24: =AVERAGEIFS(Rounds!$O:$O,Rounds!$H:$H,A24) -> 0.95428931 | D24: 0.9752 | E24: 0.7271 | F24: 0.9902 | G24: =AVERAGEIFS(Rounds!$U:$U,Rounds!$H:$H,A24) -> 6.9374046
A25: 0.1 | B25: =COUNTIFS(Rounds!$H:$H,A25) -> 3 | C25: =AVERAGEIFS(Rounds!$O:$O,Rounds!$H:$H,A25) -> 0.9299 | D25: 0.9423 | E25: 0.8825 | F25: 0.9649 | G25: =AVERAGEIFS(Rounds!$U:$U,Rounds!$H:$H,A25) -> 6.9666667
A27: sweep_half
A28: 값 | B28: n | C28: 평균 | D28: 중앙값 | E28: 최소 | F28: 최대 | G28: 평균 RMSE | H28: 메모
A29: 0.5 | B29: =COUNTIFS(Rounds!$I:$I,A29) -> 12 | C29: =AVERAGEIFS(Rounds!$O:$O,Rounds!$I:$I,A29) -> 0.86124167 | D29: 0.8795 | E29: 0.7271 | F29: 0.9509 | G29: =AVERAGEIFS(Rounds!$U:$U,Rounds!$I:$I,A29) -> 7.3416667
A30: 0.6 | B30: =COUNTIFS(Rounds!$I:$I,A30) -> 14 | C30: =AVERAGEIFS(Rounds!$O:$O,Rounds!$I:$I,A30) -> 0.89825714 | D30: 0.91555 | E30: 0.7791 | F30: 0.9726 | G30: =AVERAGEIFS(Rounds!$U:$U,Rounds!$I:$I,A30) -> 6.4785714
A31: 0.7 | B31: =COUNTIFS(Rounds!$I:$I,A31) -> 89 | C31: =AVERAGEIFS(Rounds!$O:$O,Rounds!$I:$I,A31) -> 0.9672809 | D31: 0.9768 | E31: 0.8069 | F31: 0.9902 | G31: =AVERAGEIFS(Rounds!$U:$U,Rounds!$I:$I,A31) -> 6.988764
A32: 0.8 | B32: =COUNTIFS(Rounds!$I:$I,A32) -> 23 | C32: =AVERAGEIFS(Rounds!$O:$O,Rounds!$I:$I,A32) -> 0.97225652 | D32: 0.98 | E32: 0.9441 | F32: 0.985 | G32: =AVERAGEIFS(Rounds!$U:$U,Rounds!$I:$I,A32) -> 6.8826087
A34: fit_half
A35: 값 | B35: n | C35: 평균 | D35: 중앙값 | E35: 최소 | F35: 최대 | G35: 평균 RMSE | H35: 메모
A36: 0.4 | B36: =COUNTIFS(Rounds!$J:$J,A36) -> 2 | C36: =AVERAGEIFS(Rounds!$O:$O,Rounds!$J:$J,A36) -> 0.86465 | D36: 0.86465 | E36: 0.8528 | F36: 0.8765 | G36: =AVERAGEIFS(Rounds!$U:$U,Rounds!$J:$J,A36) -> 8.15
A37: 0.5 | B37: =COUNTIFS(Rounds!$J:$J,A37) -> 29 | C37: =AVERAGEIFS(Rounds!$O:$O,Rounds!$J:$J,A37) -> 0.89093448 | D37: 0.9116 | E37: 0.7271 | F37: 0.9632 | G37: =AVERAGEIFS(Rounds!$U:$U,Rounds!$J:$J,A37) -> 7.137931
A38: 0.6 | B38: =COUNTIFS(Rounds!$J:$J,A38) -> 84 | C38: =AVERAGEIFS(Rounds!$O:$O,Rounds!$J:$J,A38) -> 0.9690369 | D38: 0.97705 | E38: 0.8394 | F38: 0.9902 | G38: =AVERAGEIFS(Rounds!$U:$U,Rounds!$J:$J,A38) -> 6.9559524
A39: 0.7 | B39: =COUNTIFS(Rounds!$J:$J,A39) -> 23 | C39: =AVERAGEIFS(Rounds!$O:$O,Rounds!$J:$J,A39) -> 0.9736913 | D39: 0.9795 | E39: 0.9251 | F39: 0.9858 | G39: =AVERAGEIFS(Rounds!$U:$U,Rounds!$J:$J,A39) -> 6.5869565
A41: samples
A42: 값 | B42: n | C42: 평균 | D42: 중앙값 | E42: 최소 | F42: 최대 | G42: 평균 RMSE | H42: 메모
A43: 1 | B43: =COUNTIFS(Rounds!$K:$K,A43) -> 9 | C43: =AVERAGEIFS(Rounds!$O:$O,Rounds!$K:$K,A43) -> 0.93956667 | D43: 0.9484 | E43: 0.9057 | F43: 0.9654 | G43: =AVERAGEIFS(Rounds!$U:$U,Rounds!$K:$K,A43) -> 10.711111
A44: 3 | B44: =COUNTIFS(Rounds!$K:$K,A44) -> 127 | C44: =AVERAGEIFS(Rounds!$O:$O,Rounds!$K:$K,A44) -> 0.95223543 | D44: 0.9752 | E44: 0.7271 | F44: 0.9902 | G44: =AVERAGEIFS(Rounds!$U:$U,Rounds!$K:$K,A44) -> 6.711811
A45: 6 | B45: =COUNTIFS(Rounds!$K:$K,A45) -> 2 | C45: =AVERAGEIFS(Rounds!$O:$O,Rounds!$K:$K,A45) -> 0.9852 | D45: 0.9852 | E45: 0.9802 | F45: 0.9902 | G45: =AVERAGEIFS(Rounds!$U:$U,Rounds!$K:$K,A45) -> 5.15
A47: 고정 조건에서의 순수 효과 (값 = 중앙값, n)
...

Sheet MBL짝비교
A1: MBL 짝 비교 — 같은 질의 세트(seed)로 4수준 교대 ×4블록 (span 0.7 / sweep 0.7 / fit 0.6 / samples 3), 14:23~14:54
A3: 블록 | B3: MBL −1.25 | C3: MBL −1.5 | D3: MBL −1.75 | E3: MBL −2.0 | F3: Δ(−1.5 − −1.25) | G3: Δ(−1.75 − −1.25) | H3: Δ(−2.0 − −1.25) | I3: noise (−1.25 / −1.5 / −1.75 / −2.0)
A4: 1 | B4: 0.9827 | C4: 0.9815 | D4: 0.9859 | E4: 0.9361 | F4: =C4-B4 -> -0.0012 | G4: =D4-B4 -> 0.0032 | H4: =E4-B4 -> -0.0466 | I4: 7.0 / 9.7 / 9.1 / 11.5
A5: 2 | B5: 0.9873 | C5: 0.9891 | D5: 0.9794 | E5: 0.9812 | F5: =C5-B5 -> 0.0018 | G5: =D5-B5 -> -0.0079 | H5: =E5-B5 -> -0.0061 | I5: 7.7 / 8.2 / 9.0 / 10.4
A6: 3 | B6: 0.9763 | C6: 0.9771 | D6: 0.9852 | E6: 0.9678 | F6: =C6-B6 -> 0.0008 | G6: =D6-B6 -> 0.0089 | H6: =E6-B6 -> -0.0085 | I6: 6.3 / 7.6 / 8.7 / 10.8
A7: 4 | B7: 0.9716 | C7: 0.9837 | D7: 0.9859 | E7: 0.9819 | F7: =C7-B7 -> 0.0121 | G7: =D7-B7 -> 0.0143 | H7: =E7-B7 -> 0.0103 | I7: 8.7 / 8.2 / 8.9 / 10.3
A8: 평균 | B8: =AVERAGE(B4:B7) -> 0.979475 | C8: =AVERAGE(C4:C7) -> 0.98285 | D8: =AVERAGE(D4:D7) -> 0.9841 | E8: =AVERAGE(E4:E7) -> 0.96675 | F8: =AVERAGE(F4:F7) -> 0.003375 | G8: =AVERAGE(G4:G7) -> 0.004625 | H8: =AVERAGE(H4:H7) -> -0.012725
A9: 중앙값 | B9: =MEDIAN(B4:B7) -> 0.9795 | C9: =MEDIAN(C4:C7) -> 0.9826 | D9: =MEDIAN(D4:D7) -> 0.98555 | E9: =MEDIAN(E4:E7) -> 0.9745 | F9: =MEDIAN(F4:F7) -> 0.0013 | G9: =MEDIAN(G4:G7) -> 0.00605 | H9: =MEDIAN(H4:H7) -> -0.0073
A11: 해석: −1.5/−1.75 는 −1.25 대비 +0.003/+0.005 (4블록 중 3~4블록 양수). −2.0 은 블록 1 에서 −0.047 (noise 11.5) 등 노이즈 증가로 손해. κ 는 186 → 204 → 226 → 238 code/V².
A13: MBL | B13: n(전체) | C13: κ 평균 | D13: 신호σ 평균 | E13: RMSE 평균 | F13: headroom 최소 | G13: depth 평균 | H13: noise 평균 | I13: 메모
A14: -1.25 | B14: 14 | C14: 186.35714 | D14: 38.428571 | E14: 5.9357143 | F14: 2081 | G14: 115.42857 | H14: 7.7714286 | I14: 전체 라운드 (span0.7/sw0.7/fit0.6/ns3)
A15: -1.5 | B15: 8 | C15: 206.875 | D15: 42.375 | E15: 6.1875 | F15: 1735 | G15: 120.625 | H15: 8.1625 | I15: 전체 라운드 (span0.7/sw0.7/fit0.6/ns3)
A16: -1.75 | B16: 13 | C16: 226.53846 | D16: 46.984615 | E16: 6.2384615 | F16: 1255 | G16: 137.61538 | H16: 9.3 | I16: 전체 라운드 (span0.7/sw0.7/fit0.6/ns3)
A17: -2 | B17: 7 | C17: 233.71429 | D17: 47.642857 | E17: 7.6428571 | F17: 666 | G17: 139.71429 | H17: 10.571429 | I17: 전체 라운드 (span0.7/sw0.7/fit0.6/ns3)

Sheet 조건별요약
A1: rank | B1: span | C1: mbl | D1: center_d | E1: sweep_half | F1: fit_half | G1: samples | H1: n | I1: median | J1: mean | K1: sd | L1: best | M1: worst | N1: rmse_q | O1: noise | P1: snr | Q1: kappa | R1: headroom_min | S1: depth | T1: t_s
A2: 1 | B2: 0.75 | C2: -2 | D2: 0 | E2: 0.7 | F2: 0.6 | G2: 3 | H2: 1 | I2: 0.9871 | J2: 0.9871 | L2: 0.9871 | M2: 0.9871 | N2: 6.6 | O2: 11.4 | P2: 8.99 | Q2: 237 | R2: 682 | S2: 129 | T2: 195.6
A3: 2 | B3: 0.75 | C3: -1.75 | D3: 0 | E3: 0.7 | F3: 0.7 | G3: 3 | H3: 1 | I3: 0.9858 | J3: 0.9858 | L3: 0.9858 | M3: 0.9858 | N3: 6.7 | O3: 10.4 | P3: 8.34 | Q3: 224 | R3: 1284 | S3: 130 | T3: 112.5
A4: 3 | B4: 0.7 | C4: -1.75 | D4: 0 | E4: 0.7 | F4: 0.6 | G4: 6 | H4: 2 | I4: 0.9852 | J4: 0.9852 | K4: 0.0070710678 | L4: 0.9902 | M4: 0.9802 | N4: 5.15 | O4: 10.9 | P4: 9.005 | Q4: 226.5 | R4: 1250 | S4: 146.5 | T4: 114.9
A5: 4 | B5: 0.7 | C5: -1.75 | D5: 0 | E5: 0.8 | F5: 0.7 | G5: 3 | H5: 1 | I5: 0.985 | J5: 0.985 | L5: 0.985 | M5: 0.985 | N5: 5.7 | O5: 8.8 | P5: 8.53 | Q5: 225 | R5: 1221 | S5: 170 | T5: 102.8
A6: 5 | B6: 0.75 | C6: -1.5 | D6: 0 | E6: 0.8 | F6: 0.6 | G6: 3 | H6: 1 | I6: 0.9844 | J6: 0.9844 | L6: 0.9844 | M6: 0.9844 | N6: 6.2 | O6: 9.4 | P6: 8.4 | Q6: 210 | R6: 1710 | S6: 142 | T6: 160
A7: 6 | B7: 0.7 | C7: -1.5 | D7: 0 | E7: 0.7 | F7: 0.7 | G7: 3 | H7: 1 | I7: 0.9841 | J7: 0.9841 | L7: 0.9841 | M7: 0.9841 | N7: 5.3 | O7: 8.4 | P7: 8.19 | Q7: 205 | R7: 1750 | S7: 120 | T7: 109.7
A8: 7 | B8: 0.7 | C8: -1.25 | D8: 0 | E8: 0.8 | F8: 0.7 | G8: 3 | H8: 1 | I8: 0.9831 | J8: 0.9831 | L8: 0.9831 | M8: 0.9831 | N8: 5.3 | O8: 8 | P8: 7.42 | Q8: 184 | R8: 2094 | S8: 147 | T8: 142.9
A9: 8 | B9: 0.75 | C9: -1.5 | D9: 0 | E9: 0.7 | F9: 0.6 | G9: 3 | H9: 1 | I9: 0.9831 | J9: 0.9831 | L9: 0.9831 | M9: 0.9831 | N9: 6.5 | O9: 7.7 | P9: 7.93 | Q9: 208 | R9: 1756 | S9: 121 | T9: 111.1
A10: 9 | B10: 0.7 | C10: -1.5 | D10: 0 | E10: 0.8 | F10: 0.6 | G10: 3 | H10: 3 | I10: 0.9819 | J10: 0.9829 | K10: 0.0018193405 | L10: 0.985 | M10: 0.9818 | N10: 5.4 | O10: 8.7 | P10: 7.95 | Q10: 213 | R10: 1714 | S10: 155 | T10: 144.6
A11: 10 | B11: 0.7 | C11: -2 | D11: 0 | E11: 0.7 | F11: 0.7 | G11: 3 | H11: 2 | I11: 0.9814 | J11: 0.9814 | K11: 0.00070710678 | L11: 0.9819 | M11: 0.9809 | N11: 6.3 | O11: 9.9 | P11: 7.575 | Q11: 238.5 | R11: 651 | S11: 146.5 | T11: 183.9
A12: 11 | B12: 0.75 | C12: -1.25 | D12: 0 | E12: 0.7 | F12: 0.7 | G12: 3 | H12: 2 | I12: 0.98135 | J12: 0.98135 | K12: 0.0044547727 | L12: 0.9845 | M12: 0.9782 | N12: 5.8 | O12: 7.25 | P12: 7.5 | Q12: 187 | R12: 2110 | S12: 104 | T12: 139.65
A13: 12 | B13: 0.7 | C13: -2 | D13: 0 | E13: 0.7 | F13: 0.6 | G13: 3 | H13: 7 | I13: 0.9812 | J13: 0.9708 | K13: 0.018061469 | L13: 0.9856 | M13: 0.9361 | N13: 7.1 | O13: 10.8 | P13: 7.23 | Q13: 235 | R13: 666 | S13: 139 | T13: 146.4
A14: 13 | B14: 0.6 | C14: -1.25 | D14: 0 | E14: 0.8 | F14: 0.6 | G14: 3 | H14: 1 | I14: 0.9808 | J14: 0.9808 | L14: 0.9808 | M14: 0.9808 | N14: 3.9 | O14: 7.9 | P14: 7.46 | Q14: 187 | R14: 2086 | S14: 151 | T14: 120
A15: 14 | B15: 0.7 | C15: -1.75 | D15: 0 | E15: 0.7 | F15: 0.7 | G15: 3 | H15: 5 | I15: 0.9807 | J15: 0.97856 | K15: 0.0046035856 | L15: 0.9834 | M15: 0.9718 | N15: 6.3 | O15: 9.3 | P15: 7.41 | Q15: 224 | R15: 1265 | S15: 141 | T15: 96.1
A16: 15 | B16: 0.7 | C16: -2 | D16: 0 | E16: 0.8 | F16: 0.6 | G16: 3 | H16: 1 | I16: 0.9805 | J16: 0.9805 | L16: 0.9805 | M16: 0.9805 | N16: 6.9 | O16: 10.2 | P16: 7.5 | Q16: 238 | R16: 651 | S16: 161 | T16: 138.3
A17: 16 | B17: 0.7 | C17: -1.75 | D17: 0 | E17: 0.7 | F17: 0.6 | G17: 3 | H17: 13 | I17: 0.9804 | J17: 0.98103077 | K17: 0.0054733269 | L17: 0.9902 | M17: 0.9722 | N17: 6.6 | O17: 9.1 | P17: 7.35 | Q17: 226 | R17: 1255 | S17: 142 | T17: 112.9
A18: 17 | B18: 0.75 | C18: -1.75 | D18: 0 | E18: 0.8 | F18: 0.6 | G18: 3 | H18: 1 | I18: 0.9803 | J18: 0.9803 | L18: 0.9803 | M18: 0.9803 | N18: 7.9 | O18: 9.7 | P18: 7.35 | Q18: 230 | R18: 1236 | S18: 174 | T18: 163.6
A19: 18 | B19: 0.75 | C19: -1.75 | D19: 0 | E19: 0.7 | F19: 0.6 | G19: 3 | H19: 3 | I19: 0.9792 | J19: 0.97876667 | K19: 0.0091576926 | L19: 0.9877 | M19: 0.9694 | N19: 8 | O19: 8.7 | P19: 7 | Q19: 224 | R19: 1240 | S19: 146 | T19: 112
A20: 19 | B20: 0.7 | C20: -1.5 | D20: 0 | E20: 0.7 | F20: 0.6 | G20: 3 | H20: 8 | I20: 0.97855 | J20: 0.9768 | K20: 0.011619319 | L20: 0.9891 | M20: 0.9501 | N20: 6.15 | O20: 8.15 | P20: 6.915 | Q20: 205 | R20: 1735 | S20: 122 | T20: 120.45
A21: 20 | B21: 0.7 | C21: -1.75 | D21: 0 | E21: 0.8 | F21: 0.6 | G21: 3 | H21: 3 | I21: 0.9775 | J21: 0.97756667 | K21: 0.0024006943 | L21: 0.98 | M21: 0.9752 | N21: 7.1 | O21: 9.8 | P21: 6.81 | Q21: 226 | R21: 1216 | S21: 164 | T21: 162.3
A22: 21 | B22: 0.7 | C22: -1.25 | D22: 0 | E22: 0.7 | F22: 0.7 | G22: 3 | H22: 5 | I22: 0.9768 | J22: 0.97414 | K22: 0.0080646141 | L22: 0.9796 | M22: 0.9602 | N22: 6 | O22: 7.9 | P22: 6.73 | Q22: 184 | R22: 2107 | S22: 101 | T22: 134.2
A23: 22 | B23: 0.6 | C23: -1.5 | D23: 0 | E23: 0.7 | F23: 0.6 | G23: 3 | H23: 1 | I23: 0.9768 | J23: 0.9768 | L23: 0.9768 | M23: 0.9768 | N23: 5.1 | O23: 7.9 | P23: 6.69 | Q23: 211 | R23: 1778 | S23: 103 | T23: 146.8
A24: 23 | B24: 0.7 | C24: -1.25 | D24: 0 | E24: 0.7 | F24: 0.6 | G24: 3 | H24: 14 | I24: 0.97515 | J24: 0.97427143 | K24: 0.010073226 | L24: 0.9873 | M24: 0.9445 | N24: 5.7 | O24: 7.55 | P24: 6.705 | Q24: 186 | R24: 2081 | S24: 117.5 | T24: 122.05
A25: 24 | B25: 0.7 | C25: -1.25 | D25: 0 | E25: 0.6 | F25: 0.6 | G25: 3 | H25: 1 | I25: 0.9726 | J25: 0.9726 | L25: 0.9726 | M25: 0.9726 | N25: 6.9 | O25: 6.6 | P25: 5.82 | Q25: 185 | R25: 2149 | S25: 83 | T25: 85.7
A26: 25 | B26: 0.75 | C26: -1.25 | D26: 0 | E26: 0.8 | F26: 0.6 | G26: 3 | H26: 4 | I26: 0.97085 | J26: 0.9676 | K26: 0.019091883 | L26: 0.9846 | M26: 0.9441 | N26: 7 | O26: 8.9 | P26: 6.495 | Q26: 191.5 | R26: 2044 | S26: 151.5 | T26: 101.3
A27: 26 | B27: 0.6 | C27: -1.25 | D27: 0 | E27: 0.7 | F27: 0.7 | G27: 3 | H27: 1 | I27: 0.9706 | J27: 0.9706 | L27: 0.9706 | M27: 0.9706 | N27: 4.8 | O27: 7.2 | P27: 6.03 | Q27: 184 | R27: 2129 | S27: 104 | T27: 206.1
A28: 27 | B28: 0.7 | C28: -1.25 | D28: 0 | E28: 0.8 | F28: 0.6 | G28: 3 | H28: 3 | I28: 0.9682 | J28: 0.9658 | K28: 0.014054537 | L28: 0.9785 | M28: 0.9507 | N28: 7.5 | O28: 9.1 | P28: 5.08 | Q28: 187 | R28: 2067 | S28: 146 | T28: 139.5
A29: 28 | B29: 0.75 | C29: -1.25 | D29: 0 | E29: 0.7 | F29: 0.6 | G29: 3 | H29: 3 | I29: 0.9661 | J29: 0.92973333 | K29: 0.07872435 | L29: 0.9837 | M29: 0.8394 | N29: 8.2 | O29: 8.8 | P29: 5.81 | Q29: 181 | R29: 2110 | S29: 113 | T29: 158.2
A30: 29 | B30: 0.7 | C30: -1.25 | D30: 0.1 | E30: 0.7 | F30: 0.6 | G30: 3 | H30: 1 | I30: 0.9649 | J30: 0.9649 | L30: 0.9649 | M30: 0.9649 | N30: 7.8 | O30: 8.6 | P30: 5.46 | Q30: 192 | R30: 2033 | S30: 117 | T30: 108.2
A31: 30 | B31: 0.7 | C31: -1.25 | D31: -0.1 | E31: 0.7 | F31: 0.6 | G31: 3 | H31: 1 | I31: 0.9618 | J31: 0.9618 | L31: 0.9618 | M31: 0.9618 | N31: 7.4 | O31: 8.1 | P31: 5.35 | Q31: 182 | R31: 2199 | S31: 112 | T31: 315.8
A32: 31 | B32: 0.7 | C32: -1.25 | D32: 0 | E32: 0.7 | F32: 0.5 | G32: 3 | H32: 2 | I32: 0.9612 | J32: 0.9612 | K32: 0.0028284271 | L32: 0.9632 | M32: 0.9592 | N32: 7.35 | O32: 7.9 | P32: 5.22 | Q32: 192.5 | R32: 2100 | S32: 115 | T32: 112.25
A33: 32 | B33: 0.75 | C33: -1.25 | D33: 0 | E33: 0.8 | F33: 0.7 | G33: 3 | H33: 2 | I33: 0.956 | J33: 0.956 | K33: 0.0090509668 | L33: 0.9624 | M33: 0.9496 | N33: 8.95 | O33: 9.45 | P33: 4.965 | Q33: 191.5 | R33: 2083 | S33: 137.5 | T33: 164.8
A34: 33 | B34: 0.75 | C34: -1.25 | D34: 0 | E34: 0.8 | F34: 0.5 | G34: 3 | H34: 2 | I34: 0.9533 | J34: 0.9533 | K34: 0.0098994949 | L34: 0.9603 | M34: 0.9463 | N34: 9.1 | O34: 8.35 | P34: 4.965 | Q34: 192 | R34: 2060 | S34: 146.5 | T34: 171.35
A35: 34 | B35: 0.6 | C35: -1.25 | D35: 0 | E35: 0.5 | F35: 0.5 | G35: 3 | H35: 1 | I35: 0.9509 | J35: 0.9509 | L35: 0.9509 | M35: 0.9509 | N35: 6.5 | O35: 7 | P35: 4.96 | Q35: 195 | R35: 2143 | S35: 67 | T35: 181.5
A36: 35 | B36: 0.6 | C36: -1.25 | D36: 0 | E36: 0.6 | F36: 0.5 | G36: 3 | H36: 2 | I36: 0.9495 | J36: 0.9495 | K36: 0.019374726 | L36: 0.9632 | M36: 0.9358 | N36: 6.1 | O36: 7.7 | P36: 4.745 | Q36: 194.5 | R36: 2138 | S36: 88 | T36: 136.5
A37: 36 | B37: 0.6 | C37: -1.25 | D37: 0 | E37: 0.7 | F37: 0.6 | G37: 3 | H37: 3 | I37: 0.9488 | J37: 0.9482 | K37: 0.0042320208 | L37: 0.9521 | M37: 0.9437 | N37: 6.6 | O37: 8.6 | P37: 4.28 | Q37: 190 | R37: 2111 | S37: 111 | T37: 130
A38: 37 | B38: 0.7 | C38: -1.75 | D38: 0 | E38: 0.7 | F38: 0.6 | G38: 1 | H38: 3 | I38: 0.9484 | J38: 0.93973333 | K38: 0.020428738 | L38: 0.9544 | M38: 0.9164 | N38: 10.8 | O38: 0 | P38: 4.31 | Q38: 230 | R38: 1281 | S38: 116 | T38: 151.8
A39: 38 | B39: 0.7 | C39: -1.75 | D39: 0 | E39: 0.7 | F39: 0.7 | G39: 1 | H39: 2 | I39: 0.94265 | J39: 0.94265 | K39: 0.024819448 | L39: 0.9602 | M39: 0.9251 | N39: 10.35 | O39: 0 | P39: 4.395 | Q39: 222 | R39: 1244 | S39: 138.5 | T39: 123.4
A40: 39 | B40: 0.5 | C40: -1.25 | D40: 0.1 | E40: 0.6 | F40: 0.5 | G40: 3 | H40: 1 | I40: 0.9423 | J40: 0.9423 | L40: 0.9423 | M40: 0.9423 | N40: 5.2 | O40: 9 | P40: 4.12 | Q40: 191 | R40: 2047 | S40: 84 | T40: 177.7
...

Sheet Cal_cells
A1: round | B1: time | C1: cond | D1: cell | E1: row | F1: col | G1: v0 | H1: se_v | I1: kappa | J1: m_code | K1: depth | L1: p_exp | M1: asym | N1: pt_sd | O1: n_pts | P1: read_v | Q1: center_v
A2: 1 | B2: 10:01:34 | C2: mbl-1.25_C-0.93_span0.50_ns3 | D2: R0C0 | E2: 0 | F2: 0 | G2: -0.0409 | H2: 0.0227 | I2: 182.2 | J2: 523.4 | K2: 63.9 | M2: 0.526 | N2: 10.95 | O2: 24 | P2: -1.25 | Q2: -0.93
A3: 1 | B3: 10:01:34 | C3: mbl-1.25_C-0.93_span0.50_ns3 | D3: R1C0 | E3: 1 | F3: 0 | G3: -0.0811 | H3: 0.0231 | I3: 165.5 | J3: 628.5 | K3: 68.2 | M3: 0.767 | N3: 11.28 | O3: 24 | P3: -1.25 | Q3: -0.93
A4: 1 | B4: 10:01:58 | C4: mbl-1.25_C-0.93_span0.50_ns3 | D4: R0C1 | E4: 0 | F4: 1 | G4: 0.0351 | H4: 0.0209 | I4: 184.4 | J4: 538.3 | K4: 70.3 | L4: 1.854 | M4: 0.889 | N4: 14.2 | O4: 25 | P4: -1.25 | Q4: -0.93
A5: 1 | B5: 10:01:58 | C5: mbl-1.25_C-0.93_span0.50_ns3 | D5: R1C1 | E5: 1 | F5: 1 | G5: -0.0116 | H5: 0.0254 | I5: 210.7 | J5: 643.3 | K5: 89.4 | L5: 5.1 | M5: 0.716 | N5: 15.56 | O5: 25 | P5: -1.25 | Q5: -0.93
A6: 2 | B6: 10:05:30 | C6: mbl-1.25_C-0.93_span0.60_ns3 | D6: R0C0 | E6: 0 | F6: 0 | G6: -0.0268 | H6: 0.0239 | I6: 167.8 | J6: 536.2 | K6: 137.5 | M6: 1.16 | N6: 11.59 | O6: 34 | P6: -1.25 | Q6: -0.93
A7: 2 | B7: 10:05:30 | C7: mbl-1.25_C-0.93_span0.60_ns3 | D7: R1C0 | E7: 1 | F7: 0 | G7: -0.0319 | H7: 0.0135 | I7: 175.5 | J7: 640 | K7: 151.3 | L7: 5.009 | M7: 1.098 | N7: 9.54 | O7: 34 | P7: -1.25 | Q7: -0.93
A8: 2 | B8: 10:06:35 | C8: mbl-1.25_C-0.93_span0.60_ns3 | D8: R0C1 | E8: 0 | F8: 1 | G8: 0.0639 | H8: 0.0173 | I8: 220.4 | J8: 536.5 | K8: 135.5 | M8: 0.83 | N8: 14.22 | O8: 34 | P8: -1.25 | Q8: -0.93
A9: 2 | B9: 10:06:35 | C9: mbl-1.25_C-0.93_span0.60_ns3 | D9: R1C1 | E9: 1 | F9: 1 | G9: 0.009 | H9: 0.0115 | I9: 216 | J9: 641.4 | K9: 134 | M9: 0.951 | N9: 10.87 | O9: 34 | P9: -1.25 | Q9: -0.93
A10: 3 | B10: 10:07:57 | C10: mbl-1.25_C-0.93_span0.70_ns3 | D10: R0C0 | E10: 0 | F10: 0 | G10: -0.047 | H10: 0.0106 | I10: 204.4 | J10: 535 | K10: 121.4 | L10: 0.276 | M10: 0.889 | N10: 7.94 | O10: 30 | P10: -1.25 | Q10: -0.93
A11: 3 | B11: 10:07:57 | C11: mbl-1.25_C-0.93_span0.70_ns3 | D11: R1C0 | E11: 1 | F11: 0 | G11: -0.0508 | H11: 0.0166 | I11: 176.3 | J11: 642.6 | K11: 119.1 | M11: 0.931 | N11: 7.18 | O11: 30 | P11: -1.25 | Q11: -0.93
A12: 3 | B12: 10:08:26 | C12: mbl-1.25_C-0.93_span0.70_ns3 | D12: R0C1 | E12: 0 | F12: 1 | G12: 0.0377 | H12: 0.0106 | I12: 198.8 | J12: 534.4 | K12: 135.2 | L12: 1.461 | M12: 0.905 | N12: 7.44 | O12: 33 | P12: -1.25 | Q12: -0.93
A13: 3 | B13: 10:08:26 | C13: mbl-1.25_C-0.93_span0.70_ns3 | D13: R1C1 | E13: 1 | F13: 1 | G13: 0.0431 | H13: 0.0088 | I13: 186.3 | J13: 641.8 | K13: 137.8 | L13: 1.638 | M13: 1.063 | N13: 7.73 | O13: 33 | P13: -1.25 | Q13: -0.93
A14: 4 | B14: 10:10:37 | C14: mbl-1.50_C-0.93_span0.50_ns3 | D14: R0C0 | E14: 0 | F14: 0 | G14: -0.0659 | H14: 0.0154 | I14: 217.7 | J14: 887.2 | K14: 109.5 | M14: 0.825 | N14: 10.76 | O14: 27 | P14: -1.5 | Q14: -0.93
A15: 4 | B15: 10:10:37 | C15: mbl-1.50_C-0.93_span0.50_ns3 | D15: R1C0 | E15: 1 | F15: 0 | G15: -0.0623 | H15: 0.0136 | I15: 188.3 | J15: 1000.4 | K15: 95.6 | L15: 1.278 | M15: 3.297 | N15: 9.81 | O15: 27 | P15: -1.5 | Q15: -0.93
A16: 4 | B16: 10:11:27 | C16: mbl-1.50_C-0.93_span0.50_ns3 | D16: R0C1 | E16: 0 | F16: 1 | G16: 0.0544 | H16: 0.0319 | I16: 184.4 | J16: 888.1 | K16: 83.5 | M16: 0.573 | N16: 9.24 | O16: 23 | P16: -1.5 | Q16: -0.93
A17: 4 | B17: 10:11:27 | C17: mbl-1.50_C-0.93_span0.50_ns3 | D17: R1C1 | E17: 1 | F17: 1 | G17: 0.0474 | H17: 0.0246 | I17: 190.6 | J17: 1000.7 | K17: 84.6 | M17: 0.513 | N17: 12.81 | O17: 23 | P17: -1.5 | Q17: -0.93
A18: 5 | B18: 10:12:55 | C18: mbl-1.50_C-0.93_span0.60_ns3 | D18: R0C0 | E18: 0 | F18: 0 | G18: -0.0513 | H18: 0.0315 | I18: 215.1 | J18: 882.6 | K18: 174.1 | L18: 2.527 | M18: 0.846 | N18: 13.17 | O18: 34 | P18: -1.5 | Q18: -0.93
A19: 5 | B19: 10:12:55 | C19: mbl-1.50_C-0.93_span0.60_ns3 | D19: R1C0 | E19: 1 | F19: 0 | G19: -0.0471 | H19: 0.012 | I19: 216.9 | J19: 997.2 | K19: 161.1 | L19: 0.318 | M19: 1.721 | N19: 11.47 | O19: 34 | P19: -1.5 | Q19: -0.93
A20: 5 | B20: 10:13:26 | C20: mbl-1.50_C-0.93_span0.60_ns3 | D20: R0C1 | E20: 0 | F20: 1 | G20: 0.0503 | H20: 0.0204 | I20: 187.9 | J20: 885 | K20: 134.3 | M20: 9.044 | N20: 12.1 | O20: 33 | P20: -1.5 | Q20: -0.93
A21: 5 | B21: 10:13:26 | C21: mbl-1.50_C-0.93_span0.60_ns3 | D21: R1C1 | E21: 1 | F21: 1 | G21: 0.072 | H21: 0.0139 | I21: 204.9 | J21: 991 | K21: 139.4 | L21: 3.75 | M21: 0.968 | N21: 13.1 | O21: 33 | P21: -1.5 | Q21: -0.93
A22: 6 | B22: 10:15:39 | C22: mbl-1.25_C-1.13_span0.50_ns3 | D22: R0C0 | E22: 0 | F22: 0 | G22: -0.024 | H22: 0.0131 | I22: 174.9 | J22: 388.6 | K22: 92.4 | L22: 2.398 | M22: 1.259 | N22: 11.28 | O22: 25 | P22: -1.25 | Q22: -1.13
A23: 6 | B23: 10:15:39 | C23: mbl-1.25_C-1.13_span0.50_ns3 | D23: R1C0 | E23: 1 | F23: 0 | G23: -0.0348 | H23: 0.0146 | I23: 186.6 | J23: 492.8 | K23: 95.5 | L23: 1.398 | M23: 0.765 | N23: 10.44 | O23: 25 | P23: -1.25 | Q23: -1.13
A24: 6 | B24: 10:16:27 | C24: mbl-1.25_C-1.13_span0.50_ns3 | D24: R0C1 | E24: 0 | F24: 1 | G24: 0.023 | H24: 0.0222 | I24: 217 | J24: 389.1 | K24: 63.9 | L24: 5.108 | M24: 1.146 | N24: 11.97 | O24: 21 | P24: -1.25 | Q24: -1.13
A25: 6 | B25: 10:16:27 | C25: mbl-1.25_C-1.13_span0.50_ns3 | D25: R1C1 | E25: 1 | F25: 1 | G25: -0.0105 | H25: 0.0194 | I25: 192 | J25: 496.3 | K25: 67 | L25: 4.317 | M25: 1.101 | N25: 12.58 | O25: 21 | P25: -1.25 | Q25: -1.13
A26: 7 | B26: 10:18:21 | C26: mbl-1.25_C-0.83_span0.50_ns3 | D26: R0C0 | E26: 0 | F26: 0 | G26: -0.0411 | H26: 0.0175 | I26: 193.4 | J26: 619.9 | K26: 74.1 | M26: 0.392 | N26: 11.68 | O26: 24 | P26: -1.25 | Q26: -0.83
A27: 7 | B27: 10:18:21 | C27: mbl-1.25_C-0.83_span0.50_ns3 | D27: R1C0 | E27: 1 | F27: 0 | G27: -0.0437 | H27: 0.0128 | I27: 181.8 | J27: 729.3 | K27: 76 | M27: 1.04 | N27: 8.16 | O27: 24 | P27: -1.25 | Q27: -0.83
A28: 7 | B28: 10:19:11 | C28: mbl-1.25_C-0.83_span0.50_ns3 | D28: R0C1 | E28: 0 | F28: 1 | G28: 0.0466 | H28: 0.0248 | I28: 191 | J28: 617.8 | K28: 57.2 | M28: 1.473 | N28: 10.4 | O28: 23 | P28: -1.25 | Q28: -0.83
A29: 7 | B29: 10:19:11 | C29: mbl-1.25_C-0.83_span0.50_ns3 | D29: R1C1 | E29: 1 | F29: 1 | G29: 0.0188 | H29: 0.0307 | I29: 167.7 | J29: 731.5 | K29: 57.5 | L29: 0.881 | M29: 0.785 | N29: 12.54 | O29: 23 | P29: -1.25 | Q29: -0.83
A30: 8 | B30: 10:19:52 | C30: mbl-1.25_C-0.93_span0.50_ns3 | D30: R0C0 | E30: 0 | F30: 0 | G30: -0.0224 | H30: 0.0159 | I30: 190.1 | J30: 537.3 | K30: 52 | L30: 4.656 | M30: 0.868 | N30: 9.13 | O30: 21 | P30: -1.25 | Q30: -0.93
A31: 8 | B31: 10:19:52 | C31: mbl-1.25_C-0.93_span0.50_ns3 | D31: R1C0 | E31: 1 | F31: 0 | G31: -0.0505 | H31: 0.0229 | I31: 177 | J31: 643.4 | K31: 60.9 | M31: 1.602 | N31: 11.08 | O31: 21 | P31: -1.25 | Q31: -0.93
A32: 8 | B32: 10:20:18 | C32: mbl-1.25_C-0.93_span0.50_ns3 | D32: R0C1 | E32: 0 | F32: 1 | G32: 0.0543 | H32: 0.0201 | I32: 215 | J32: 532.3 | K32: 112.7 | M32: 0.123 | N32: 11.27 | O32: 29 | P32: -1.25 | Q32: -0.93
A33: 8 | B33: 10:20:18 | C33: mbl-1.25_C-0.93_span0.50_ns3 | D33: R1C1 | E33: 1 | F33: 1 | G33: 0.0382 | H33: 0.0459 | I33: 182.2 | J33: 646.7 | K33: 96 | M33: 1.042 | N33: 12.26 | O33: 29 | P33: -1.25 | Q33: -0.93
A34: 9 | B34: 10:24:36 | C34: mbl-1.25_C-0.93_span0.50_ns3 | D34: R0C0 | E34: 0 | F34: 0 | G34: -0.0601 | H34: 0.0143 | I34: 185.8 | J34: 531.1 | K34: 76.2 | M34: 1.007 | N34: 13.72 | O34: 26 | P34: -1.25 | Q34: -0.93
A35: 9 | B35: 10:24:36 | C35: mbl-1.25_C-0.93_span0.50_ns3 | D35: R1C0 | E35: 1 | F35: 0 | G35: -0.0448 | H35: 0.0122 | I35: 203.8 | J35: 636.7 | K35: 92 | L35: 4.875 | M35: 1.833 | N35: 10.09 | O35: 26 | P35: -1.25 | Q35: -0.93
A36: 9 | B36: 10:25:01 | C36: mbl-1.25_C-0.93_span0.50_ns3 | D36: R0C1 | E36: 0 | F36: 1 | G36: 0.0433 | H36: 0.0116 | I36: 186 | J36: 531.6 | K36: 79 | L36: 3.955 | M36: 0.559 | N36: 11.41 | O36: 25 | P36: -1.25 | Q36: -0.93
A37: 9 | B37: 10:25:01 | C37: mbl-1.25_C-0.93_span0.50_ns3 | D37: R1C1 | E37: 1 | F37: 1 | G37: 0.0282 | H37: 0.0136 | I37: 208.2 | J37: 636 | K37: 84.3 | L37: 4.079 | M37: 0.366 | N37: 12.1 | O37: 25 | P37: -1.25 | Q37: -0.93
A38: 10 | B38: 10:25:58 | C38: mbl-1.00_C-0.93_span0.50_ns3 | D38: R0C0 | E38: 0 | F38: 0 | G38: -0.0347 | H38: 0.0252 | I38: 146.4 | J38: 293.6 | K38: 62 | M38: 2 | N38: 12.09 | O38: 26 | P38: -1 | Q38: -0.93
A39: 10 | B39: 10:25:58 | C39: mbl-1.00_C-0.93_span0.50_ns3 | D39: R1C0 | E39: 1 | F39: 0 | G39: -0.0264 | H39: 0.0198 | I39: 141.2 | J39: 395.2 | K39: 64.8 | L39: 0.623 | M39: 1.286 | N39: 9.12 | O39: 26 | P39: -1 | Q39: -0.93
A40: 10 | B40: 10:26:50 | C40: mbl-1.00_C-0.93_span0.50_ns3 | D40: R0C1 | E40: 0 | F40: 1 | G40: 0.0042 | H40: 0.0144 | I40: 237.8 | J40: 286.3 | K40: 69.4 | L40: 1.427 | M40: 1.409 | N40: 14.19 | O40: 26 | P40: -1 | Q40: -0.93
...

Sheet Best_round_points
A1: 라운드 64 (12:39:30) — span 0.7 / MBL -1.75 / C -0.93 / sweep 0.7 / fit 0.6 / samples 3 → score 0.9902, 2차 R² 0.990/0.991, RMSE 4.8, noise 9.0
A3: q | B3: x0 [V] | C3: x1 [V] | D3: row | E3: code 측정 | F3: code 예측(2차) | G3: 잔차 | H3: code 예측(곡선) | I3: 잔차(곡선) | J3: excess 측정 | K3: excess 예측 | L3: D_cal [V²] | M3: 샘플 sd
A4: 0 | B4: 0.0479 | C4: -0.2246 | D4: 0 | E4: 1362.33 | F4: 1368.63 | G4: -6.29 | H4: 1369.21 | I4: -6.87 | J4: 22.75 | K4: 29.04 | L4: 29.039 | M4: 8.14
A5: 0 | B5: 0.0479 | C5: -0.2246 | D5: 1 | E5: 1480 | F5: 1482.53 | G5: -2.53 | H5: 1485.94 | I5: -5.94 | J5: 22.46 | K5: 24.99 | L5: 24.99 | M5: 4.58
A6: 1 | B6: 0.23 | C6: 0.1221 | D6: 0 | E6: 1353.67 | F6: 1361.04 | G6: -7.38 | H6: 1372.05 | I6: -18.39 | J6: 14.08 | K6: 21.46 | L6: 21.456 | M6: 4.62
A7: 1 | B7: 0.23 | C7: 0.1221 | D7: 1 | E7: 1482.67 | F7: 1476.99 | G7: 5.67 | H7: 1471.14 | I7: 11.52 | J7: 25.12 | K7: 19.45 | L7: 19.449 | M7: 10.41
A8: 2 | B8: 0.4829 | C8: -0.4599 | D8: 0 | E8: 1490 | F8: 1483.96 | G8: 6.04 | H8: 1490.69 | I8: -0.69 | J8: 150.41 | K8: 144.37 | L8: 144.374 | M8: 4.36
A9: 2 | B9: 0.4829 | C9: -0.4599 | D9: 1 | E9: 1595 | F9: 1589.17 | G9: 5.83 | H9: 1593.43 | I9: 1.57 | J9: 137.46 | K9: 131.63 | L9: 131.63 | M9: 4.58
A10: 3 | B10: 0.2532 | C10: -0.2847 | D10: 0 | E10: 1407.67 | F10: 1399.71 | G10: 7.96 | H10: 1409.01 | I10: -1.35 | J10: 68.08 | K10: 60.12 | L10: 60.123 | M10: 7.09
A11: 3 | B11: 0.2532 | C11: -0.2847 | D11: 1 | E11: 1515 | F11: 1510.92 | G11: 4.08 | H11: 1501.86 | I11: 13.14 | J11: 57.46 | K11: 53.37 | L11: 53.372 | M11: 11.36
A12: 4 | B12: -0.3579 | C12: 0.7047 | D12: 0 | E12: 1440.67 | F12: 1433.51 | G12: 7.16 | H12: 1454.18 | I12: -13.51 | J12: 101.08 | K12: 93.92 | L12: 93.923 | M12: 7.77
A13: 4 | B13: -0.3579 | C13: 0.7047 | D13: 1 | E13: 1563.33 | F13: 1558.28 | G13: 5.06 | H13: 1558.23 | I13: 5.11 | J13: 105.79 | K13: 100.73 | L13: 100.732 | M13: 12.01
A14: 5 | B14: -0.5979 | C14: 0.1945 | D14: 0 | E14: 1397.33 | F14: 1403.26 | G14: -5.92 | H14: 1407.36 | I14: -10.02 | J14: 57.75 | K14: 63.67 | L14: 63.671 | M14: 4.62
A15: 5 | B15: -0.5979 | C15: 0.1945 | D15: 1 | E15: 1519.33 | F15: 1517.46 | G15: 1.87 | H15: 1521.18 | I15: -1.85 | J15: 61.79 | K15: 59.92 | L15: 59.917 | M15: 15.04
... A51: 23 | B51: 0.2535 | C51: -0.0437 | D51: 1 | E51: 1489 | F51: 1483.81 | G51: 5.19 | H51: 1475.17 | I51: 13.83 | J51: 31.46 | K51: 26.27 | L51: 26.266 | M51: 6.24
A53: 검산 (수식)
A54: row0 | B54: R² | C54: =1-SUMPRODUCT((D4:D51=0)*(G4:G51)^2)/SUMPRODUCT((D4:D51=0)*(E4:E51-AVERAGEIF(D4:D51,0,E4:E51))^2) -> 0.98978983 | D54: RMSE | E54: =SQRT(SUMPRODUCT((D4:D51=0)*(G4:G51)^2)/COUNTIF(D4:D51,0)) -> 5.0071532
